<robot
  name="owr_numbat_tf">
  <link
    name="base_link">
    <inertial>
      <origin
        xyz="0.199001521355698 0.401976534326884 0.644578776800536"
        rpy="0 0 0" />
      <mass
        value="33.4975943636999" />
      <inertia
        ixx="0.0125052741751253"
        ixy="0.00142309072234029"
        ixz="0.00557644568946697"
        iyy="0.0456048995470643"
        iyz="0.000645084117129033"
        izz="0.0337193883299707" />
    </inertial>
    <visual>
      <origin
        xyz="0 0 0"
        rpy="0 0 0" />
      <geometry>
        <mesh
          filename="package://owr_numbat_tf/meshes/base_link.STL" />
      </geometry>
      <material
        name="">
        <color
          rgba="0.792156862745098 0.819607843137255 0.933333333333333 1" />
      </material>
    </visual>
    <collision>
      <origin
        xyz="0 0 0"
        rpy="0 0 0" />
      <geometry>
        <mesh
          filename="package://owr_numbat_tf/meshes/base_link.STL" />
      </geometry>
    </collision>
  </link>
  <link
    name="Front Left Axle">
    <inertial>
      <origin
        xyz="-0.0517688079644882 0.0887190484893181 2.22044604925031E-16"
        rpy="0 0 0" />
      <mass
        value="0.674113164049984" />
      <inertia
        ixx="0"
        ixy="0"
        ixz="0"
        iyy="0"
        iyz="0"
        izz="0" />
    </inertial>
    <visual>
      <origin
        xyz="0 0 0"
        rpy="0 0 0" />
      <geometry>
        <mesh
          filename="package://owr_numbat_tf/meshes/Front Left Axle.STL" />
      </geometry>
      <material
        name="">
        <color
          rgba="0.792156862745098 0.819607843137255 0.933333333333333 1" />
      </material>
    </visual>
    <collision>
      <origin
        xyz="0 0 0"
        rpy="0 0 0" />
      <geometry>
        <mesh
          filename="package://owr_numbat_tf/meshes/Front Left Axle.STL" />
      </geometry>
    </collision>
  </link>
  <joint
    name="Front Left Steer"
    type="continuous">
    <origin
      xyz="0.62684 -0.40335 0.13495"
      rpy="1.5708 6.088E-17 1.6778" />
    <parent
      link="base_link" />
    <child
      link="Front Left Axle" />
    <axis
      xyz="0 1 0" />
  </joint>
  <link
    name="Front Left wheel">
    <inertial>
      <origin
        xyz="6.06240746492404E-09 -2.77011136112781E-07 -0.00589838982095087"
        rpy="0 0 0" />
      <mass
        value="1.5442893046468" />
      <inertia
        ixx="0"
        ixy="0"
        ixz="0"
        iyy="0"
        iyz="0"
        izz="0" />
    </inertial>
    <visual>
      <origin
        xyz="0 0 0"
        rpy="0 0 0" />
      <geometry>
        <mesh
          filename="package://owr_numbat_tf/meshes/Front Left wheel.STL" />
      </geometry>
      <material
        name="">
        <color
          rgba="0.792156862745098 0.819607843137255 0.933333333333333 1" />
      </material>
    </visual>
    <collision>
      <origin
        xyz="0 0 0"
        rpy="0 0 0" />
      <geometry>
        <mesh
          filename="package://owr_numbat_tf/meshes/Front Left wheel.STL" />
      </geometry>
    </collision>
  </link>
  <joint
    name="Front Left rotate"
    type="continuous">
    <origin
      xyz="0 0.03 0"
      rpy="-1.5708 -0.91526 1.5708" />
    <parent
      link="Front Left Axle" />
    <child
      link="Front Left wheel" />
    <axis
      xyz="0 0 1" />
  </joint>
  <link
    name="Back Left Axle">
    <inertial>
      <origin
        xyz="-0.0517688079644883 0.0887190484893179 -4.16333634234434E-17"
        rpy="0 0 0" />
      <mass
        value="0.674113164049983" />
      <inertia
        ixx="0"
        ixy="0"
        ixz="0"
        iyy="0"
        iyz="0"
        izz="0" />
    </inertial>
    <visual>
      <origin
        xyz="0 0 0"
        rpy="0 0 0" />
      <geometry>
        <mesh
          filename="package://owr_numbat_tf/meshes/Back Left Axle.STL" />
      </geometry>
      <material
        name="">
        <color
          rgba="0.792156862745098 0.819607843137255 0.933333333333333 1" />
      </material>
    </visual>
    <collision>
      <origin
        xyz="0 0 0"
        rpy="0 0 0" />
      <geometry>
        <mesh
          filename="package://owr_numbat_tf/meshes/Back Left Axle.STL" />
      </geometry>
    </collision>
  </link>
  <joint
    name="Back Left Steer"
    type="continuous">
    <origin
      xyz="-0.13031 -0.40335 0.13495"
      rpy="1.5708 6.0901E-17 1.4671" />
    <parent
      link="base_link" />
    <child
      link="Back Left Axle" />
    <axis
      xyz="0 1 0" />
  </joint>
  <link
    name="Back Left Wheel">
    <inertial>
      <origin
        xyz="6.06240754819076E-09 -2.77011136001759E-07 -0.00589838982095175"
        rpy="0 0 0" />
      <mass
        value="1.5442893046468" />
      <inertia
        ixx="0"
        ixy="0"
        ixz="0"
        iyy="0"
        iyz="0"
        izz="0" />
    </inertial>
    <visual>
      <origin
        xyz="0 0 0"
        rpy="0 0 0" />
      <geometry>
        <mesh
          filename="package://owr_numbat_tf/meshes/Back Left Wheel.STL" />
      </geometry>
      <material
        name="">
        <color
          rgba="0.792156862745098 0.819607843137255 0.933333333333333 1" />
      </material>
    </visual>
    <collision>
      <origin
        xyz="0 0 0"
        rpy="0 0 0" />
      <geometry>
        <mesh
          filename="package://owr_numbat_tf/meshes/Back Left Wheel.STL" />
      </geometry>
    </collision>
  </link>
  <joint
    name="Back Left Rotate"
    type="continuous">
    <origin
      xyz="0 0.0300000000000001 0"
      rpy="1.57079632679489 0.214040970418392 -1.5707963267949" />
    <parent
      link="Back Left Axle" />
    <child
      link="Back Left Wheel" />
    <axis
      xyz="0 0 1" />
  </joint>
  <link
    name="Back Right Axle">
    <inertial>
      <origin
        xyz="-0.0517688079644882 0.088719048489318 -5.55111512312578E-17"
        rpy="0 0 0" />
      <mass
        value="0.674113164049983" />
      <inertia
        ixx="0"
        ixy="0"
        ixz="0"
        iyy="0"
        iyz="0"
        izz="0" />
    </inertial>
    <visual>
      <origin
        xyz="0 0 0"
        rpy="0 0 0" />
      <geometry>
        <mesh
          filename="package://owr_numbat_tf/meshes/Back Right Axle.STL" />
      </geometry>
      <material
        name="">
        <color
          rgba="0.792156862745098 0.819607843137255 0.933333333333333 1" />
      </material>
    </visual>
    <collision>
      <origin
        xyz="0 0 0"
        rpy="0 0 0" />
      <geometry>
        <mesh
          filename="package://owr_numbat_tf/meshes/Back Right Axle.STL" />
      </geometry>
    </collision>
  </link>
  <joint
    name="Back Right Steer"
    type="continuous">
    <origin
      xyz="-0.13031 -0.88449 0.13495"
      rpy="1.5708 5.9043E-17 1.3027" />
    <parent
      link="base_link" />
    <child
      link="Back Right Axle" />
    <axis
      xyz="0 1 0" />
  </joint>
  <link
    name="Back Right Wheel">
    <inertial>
      <origin
        xyz="6.06240740941288E-09 -2.77011135974004E-07 -0.00589838982095114"
        rpy="0 0 0" />
      <mass
        value="1.54428930464679" />
      <inertia
        ixx="0"
        ixy="0"
        ixz="0"
        iyy="0"
        iyz="0"
        izz="0" />
    </inertial>
    <visual>
      <origin
        xyz="0 0 0"
        rpy="0 0 0" />
      <geometry>
        <mesh
          filename="package://owr_numbat_tf/meshes/Back Right Wheel.STL" />
      </geometry>
      <material
        name="">
        <color
          rgba="0.792156862745098 0.819607843137255 0.933333333333333 1" />
      </material>
    </visual>
    <collision>
      <origin
        xyz="0 0 0"
        rpy="0 0 0" />
      <geometry>
        <mesh
          filename="package://owr_numbat_tf/meshes/Back Right Wheel.STL" />
      </geometry>
    </collision>
  </link>
  <joint
    name="Back RIght Rotate"
    type="continuous">
    <origin
      xyz="0 0.0299999999999999 0"
      rpy="-1.57079632679491 -1.13219561486008 1.57079632679491" />
    <parent
      link="Back Right Axle" />
    <child
      link="Back Right Wheel" />
    <axis
      xyz="0 0 1" />
  </joint>
  <link
    name="Front Right Axle">
    <inertial>
      <origin
        xyz="-0.0517688079644884 0.088719048489318 -2.22044604925031E-16"
        rpy="0 0 0" />
      <mass
        value="0.674113164049983" />
      <inertia
        ixx="0"
        ixy="0"
        ixz="0"
        iyy="0"
        iyz="0"
        izz="0" />
    </inertial>
    <visual>
      <origin
        xyz="0 0 0"
        rpy="0 0 0" />
      <geometry>
        <mesh
          filename="package://owr_numbat_tf/meshes/Front Right Axle.STL" />
      </geometry>
      <material
        name="">
        <color
          rgba="0.792156862745098 0.819607843137255 0.933333333333333 1" />
      </material>
    </visual>
    <collision>
      <origin
        xyz="0 0 0"
        rpy="0 0 0" />
      <geometry>
        <mesh
          filename="package://owr_numbat_tf/meshes/Front Right Axle.STL" />
      </geometry>
    </collision>
  </link>
  <joint
    name="Front Right Steer"
    type="continuous">
    <origin
      xyz="0.626839262679528 -0.884494656994069 0.13494946923044"
      rpy="1.5707963267949 6.12114355045412E-17 1.54596104769157" />
    <parent
      link="base_link" />
    <child
      link="Front Right Axle" />
    <axis
      xyz="0 1 0" />
  </joint>
  <link
    name="Front RIght Wheel">
    <inertial>
      <origin
        xyz="6.10794798072689E-09 -2.76999337467387E-07 -0.00589838982429747"
        rpy="0 0 0" />
      <mass
        value="1.54428930379881" />
      <inertia
        ixx="0"
        ixy="0"
        ixz="0"
        iyy="0"
        iyz="0"
        izz="0" />
    </inertial>
    <visual>
      <origin
        xyz="0 0 0"
        rpy="0 0 0" />
      <geometry>
        <mesh
          filename="package://owr_numbat_tf/meshes/Front RIght Wheel.STL" />
      </geometry>
      <material
        name="">
        <color
          rgba="0.792156862745098 0.819607843137255 0.933333333333333 1" />
      </material>
    </visual>
    <collision>
      <origin
        xyz="0 0 0"
        rpy="0 0 0" />
      <geometry>
        <mesh
          filename="package://owr_numbat_tf/meshes/Front RIght Wheel.STL" />
      </geometry>
    </collision>
  </link>
  <joint
    name="Front Right Rotate"
    type="continuous">
    <origin
      xyz="0 0.0299999999999999 0"
      rpy="-1.5707963267949 -0.00858284690216311 1.57079632679489" />
    <parent
      link="Front Right Axle" />
    <child
      link="Front RIght Wheel" />
    <axis
      xyz="0 0 1" />
  </joint>
</robot>