<?xml version="1.0"?>
<robot xmlns:xacro="http://www.ros.org/wiki/xacro" name="owr_bluetounge2_tf">
	 <link name="base_stabalized_frame"></link>
	 <joint
        name="base_footprint_joint"
        type="fixed">
        <origin
        xyz="0 0 0 "
        rpy="0 0 0" />
        <parent
        link="base_footprint" />
        <child
        link="base_link" />
        <axis
        xyz="0 0 0" />
    </joint>
    <link name="base_link">
    </link>
    <joint
        name="base_link_joint"
        type="fixed">
        <origin
        xyz="0 0 0 "
        rpy="0 0 0" />
        <parent
        link="base_link" />
        <child
        link="chassis" />
        <axis
        xyz="0 0 0" />
    </joint>
  <link
    name="chassis">
    <inertial>
      <origin
        xyz="-0.000306092356492482 0.000502740394013363 0.0553311735203667"
        rpy="0 0 0" />
      <mass
        value="6.57554175926752" />
      <inertia
        ixx="0.130336756755182"
        ixy="0.000985293057339753"
        ixz="-0.000105850627883423"
        iyy="0.253408028783963"
        iyz="0.00010300338303658"
        izz="0.352162668028523" />
    </inertial>
    <visual>
      <origin
        xyz="0 0 0"
        rpy="0 0 0" />
      <geometry>
        <mesh
          filename="package://owr_bluetounge2_tf/meshes/base_link.STL" />
      </geometry>
      <material
        name="">
        <color
          rgba="0.898039215686275 0.917647058823529 0.929411764705882 1" />
      </material>
    </visual>
    <collision>
      <origin
        xyz="0 0 0"
        rpy="0 0 0" />
      <geometry>
        <mesh
          filename="package://owr_bluetounge2_tf/meshes/base_link.STL" />
      </geometry>
    </collision>
  </link>
  <link
    name="laser_tilt">
    <inertial>
      <origin
        xyz="-0.0326669331300311 0.000449239090195036 0.0154731252391825"
        rpy="0 0 0" />
      <mass
        value="0.0609125923338383" />
      <inertia
        ixx="2.00361198600938E-05"
        ixy="-5.20398520467511E-07"
        ixz="1.67772001955164E-06"
        iyy="5.68087099458121E-05"
        iyz="-4.03110668527991E-08"
        izz="5.87542018274252E-05" />
    </inertial>
    <visual>
      <origin
        xyz="0 0 0"
        rpy="0 0 0" />
      <geometry>
        <mesh
          filename="package://owr_bluetounge2_tf/meshes/laser_tilt.STL" />
      </geometry>
      <material
        name="">
        <color
          rgba="0.792156862745098 0.819607843137255 0.933333333333333 1" />
      </material>
    </visual>
    <collision>
      <origin
        xyz="0 0 0"
        rpy="0 0 0" />
      <geometry>
        <mesh
          filename="package://owr_bluetounge2_tf/meshes/laser_tilt.STL" />
      </geometry>
    </collision>
  </link>
  <joint
    name="laser_tilt_base"
    type="fixed">
    <origin
      xyz="0.26213671627839 0.165813347998531 0.116"
      rpy="-4.0766001685455E-16 -2.71143453751384E-15 -7.14214183115679E-19" />
    <parent
      link="chassis" />
    <child
      link="laser_tilt" />
    <axis
      xyz="0 0 0" />
  </joint>
  <link
    name="laser_tilt_tilt">
    <inertial>
      <origin
        xyz="-0.0207354942246256 -0.0110062171521322 0.0363962516011186"
        rpy="0 0 0" />
      <mass
        value="0.063245803268312" />
      <inertia
        ixx="3.67872840111064E-05"
        ixy="2.45249846765993E-06"
        ixz="1.33088294535402E-06"
        iyy="4.06730444934804E-05"
        iyz="6.96179679390717E-07"
        izz="4.48239101958926E-05" />
    </inertial>
    <visual>
      <origin
        xyz="0 0 0"
        rpy="0 0 0" />
      <geometry>
        <mesh
          filename="package://owr_bluetounge2_tf/meshes/laser_tilt_tilt.STL" />
      </geometry>
      <material
        name="">
        <color
          rgba="0.792156862745098 0.819607843137255 0.933333333333333 1" />
      </material>
    </visual>
    <collision>
      <origin
        xyz="0 0 0"
        rpy="0 0 0" />
      <geometry>
        <mesh
          filename="package://owr_bluetounge2_tf/meshes/laser_tilt_tilt.STL" />
      </geometry>
    </collision>
  </link>
  <joint
    name="laser_tilt_joint"
    type="revolute">
    <origin
      xyz="-0.00692854336717914 -0.01905 0.029"
      rpy="-1.5707963267949 1.08521967863993 0" />
    <parent
      link="laser_tilt" />
    <child
      link="laser_tilt_tilt" />
    <axis
      xyz="0 0 1" />
    <limit
      lower="-0.785398"
      upper="1.5708"
      effort="0"
      velocity="0" />
  </joint>
  <link
    name="lidar_frame">
    <inertial>
      <origin
        xyz="-0.000639925729432167 0.000662656077548368 -0.0176677612707939"
        rpy="0 0 0" />
      <mass
        value="0.229160254803044" />
      <inertia
        ixx="0.000208997482925673"
        ixy="4.81938834051271E-07"
        ixz="1.1237905876103E-06"
        iyy="0.000213298877696199"
        iyz="1.24374624615713E-07"
        izz="0.000112442329412222" />
    </inertial>
    <visual>
      <origin
        xyz="0 0 0"
        rpy="0 0 0" />
      <geometry>
        <mesh
          filename="package://owr_bluetounge2_tf/meshes/lidar_frame.STL" />
      </geometry>
      <material
        name="">
        <color
          rgba="0 0 0 1" />
      </material>
    </visual>
    <collision>
      <origin
        xyz="0 0 0"
        rpy="0 0 0" />
      <geometry>
        <mesh
          filename="package://owr_bluetounge2_tf/meshes/lidar_frame.STL" />
      </geometry>
    </collision>
  </link>
  <joint
    name="lidar_frame_base"
    type="fixed">
    <origin
      xyz="-0.0922144508966998 -0.0394134633802184 0.0346559749585283"
      rpy="1.5707963267949 0.110221873047514 -1.08521967863993" />
    <parent
      link="laser_tilt_tilt" />
    <child
      link="lidar_frame" />
    <axis
      xyz="0 0 0" />
  </joint>
  <link
    name="front_left_leg_base">
    <inertial>
      <origin
        xyz="0 0.00294015084396301 0.0195712415755609"
        rpy="0 0 0" />
      <mass
        value="0.0851788397766331" />
      <inertia
        ixx="4.20226124478786E-05"
        ixy="-3.82162266421485E-22"
        ixz="-4.96572886579277E-22"
        iyy="3.11208969345462E-05"
        iyz="-7.80560663932167E-07"
        izz="4.60535086117171E-05" />
    </inertial>
    <visual>
      <origin
        xyz="0 0 0"
        rpy="0 0 0" />
      <geometry>
        <mesh
          filename="package://owr_bluetounge2_tf/meshes/front_left_leg_base.STL" />
      </geometry>
      <material
        name="">
        <color
          rgba="0.101960784313725 0.101960784313725 0.101960784313725 1" />
      </material>
    </visual>
    <collision>
      <origin
        xyz="0 0 0"
        rpy="0 0 0" />
      <geometry>
        <mesh
          filename="package://owr_bluetounge2_tf/meshes/front_left_leg_base.STL" />
      </geometry>
    </collision>
  </link>
  <joint
    name="front_left_leg_base_joint"
    type="fixed">
    <origin
      xyz="0.271043058686069 0.22581334799853 0.106000000000001"
      rpy="-3.14159265358979 -7.45286116330806E-17 3.14159265358979" />
    <parent
      link="chassis" />
    <child
      link="front_left_leg_base" />
    <axis
      xyz="0 0 0" />
  </joint>
  <link
    name="front_left_leg_top">
    <inertial>
      <origin
        xyz="-0.0118602854136348 -0.0016720264699957 0.0475197676666218"
        rpy="0 0 0" />
      <mass
        value="0.21598270894823" />
      <inertia
        ixx="0.000388027009972353"
        ixy="-3.85254528971199E-06"
        ixz="9.50531691047562E-06"
        iyy="0.00110375596772869"
        iyz="-2.09277988001819E-07"
        izz="0.000790912964197712" />
    </inertial>
    <visual>
      <origin
        xyz="0 0 0"
        rpy="0 0 0" />
      <geometry>
        <mesh
          filename="package://owr_bluetounge2_tf/meshes/front_left_leg_top.STL" />
      </geometry>
      <material
        name="">
        <color
          rgba="0.101960784313725 0.101960784313725 0.101960784313725 1" />
      </material>
    </visual>
    <collision>
      <origin
        xyz="0 0 0"
        rpy="0 0 0" />
      <geometry>
        <mesh
          filename="package://owr_bluetounge2_tf/meshes/front_left_leg_top.STL" />
      </geometry>
    </collision>
  </link>
  <joint
    name="front_left_leg_top_suspension"
    type="fixed">
    <origin
      xyz="-0.0481 0.0906125308820751 0.00192206350156074"
      rpy="1.5707963267949 0.208107268180907 1.5707963267949" />
    <parent
      link="front_left_leg_base" />
    <child
      link="front_left_leg_top" />
    <axis
      xyz="0 0 1" />
  </joint>
  <link
    name="front_left_swerve_top">
    <inertial>
      <origin
        xyz="0.00579106512736 -0.0190503342420132 -0.0544162570868618"
        rpy="0 0 0" />
      <mass
        value="0.106275788707863" />
      <inertia
        ixx="0.000384207493948846"
        ixy="8.31400403854648E-10"
        ixz="-2.53474601873918E-05"
        iyy="0.000312868634094906"
        iyz="-2.3572655118053E-09"
        izz="0.000111979641603734" />
    </inertial>
    <visual>
      <origin
        xyz="0 0 0"
        rpy="0 0 0" />
      <geometry>
        <mesh
          filename="package://owr_bluetounge2_tf/meshes/front_left_swerve_top.STL" />
      </geometry>
      <material
        name="">
        <color
          rgba="0.898039215686275 0.92156862745098 0.929411764705882 1" />
      </material>
    </visual>
    <collision>
      <origin
        xyz="0 0 0"
        rpy="0 0 0" />
      <geometry>
        <mesh
          filename="package://owr_bluetounge2_tf/meshes/front_left_swerve_top.STL" />
      </geometry>
    </collision>
  </link>
  <joint
    name="front_left_swerve_to_suspension"
    type="fixed">
    <origin
      xyz="0.0875 0 0.06715"
      rpy="1.5707963267949 -6.479054612879E-16 0.297543712362438" />
    <parent
      link="front_left_leg_top" />
    <child
      link="front_left_swerve_top" />
    <axis
      xyz="0 -1 0" />
  </joint>
  <link
    name="front_left_swerve_axel">
    <inertial>
      <origin
        xyz="0.0799583398916556 0.0493805695532939 -1.53687481296849E-06"
        rpy="0 0 0" />
      <mass
        value="2.36761790939096" />
      <inertia
        ixx="0.0114180394512723"
        ixy="-0.00137524896528127"
        ixz="1.6509995191638E-07"
        iyy="0.00616871388104346"
        iyz="9.2483675722695E-08"
        izz="0.016168223679751" />
    </inertial>
    <visual>
      <origin
        xyz="0 0 0"
        rpy="0 0 0" />
      <geometry>
        <mesh
          filename="package://owr_bluetounge2_tf/meshes/front_left_swerve_axel.STL" />
      </geometry>
      <material
        name="">
        <color
          rgba="0.898039215686275 0.92156862745098 0.929411764705882 1" />
      </material>
    </visual>
    <collision>
      <origin
        xyz="0 0 0"
        rpy="0 0 0" />
      <geometry>
        <mesh
          filename="package://owr_bluetounge2_tf/meshes/front_left_swerve_axel.STL" />
      </geometry>
    </collision>
  </link>
  <joint
    name="front_left_swerve"
    type="continuous">
    <origin
      xyz="0.012974001894102 -0.0190500000000023 -0.144676938663704"
      rpy="1.51681695722705 1.48135988261336 -1.93089679672663E-15" />
    <parent
      link="front_left_swerve_top" />
    <child
      link="front_left_swerve_axel" />
    <axis
      xyz="1 0 0" />
  </joint>
  <link
    name="front_left_wheel">
    <inertial>
      <origin
        xyz="-0.0663813744814108 -1.95940016273766E-05 -2.22091400667035E-05"
        rpy="0 0 0" />
      <mass
        value="2.15472811624945" />
      <inertia
        ixx="0.0180021390861626"
        ixy="6.42530610884086E-07"
        ixz="7.28286779065905E-07"
        iyy="0.0154652772226983"
        iyz="-1.72296508626635E-07"
        izz="0.0154653205064802" />
    </inertial>
    <visual>
      <origin
        xyz="0 0 0"
        rpy="0 0 0" />
      <geometry>
        <mesh
          filename="package://owr_bluetounge2_tf/meshes/front_left_wheel.STL" />
      </geometry>
      <material
        name="">
        <color
          rgba="0.294117647058824 0.294117647058824 0.294117647058824 1" />
      </material>
    </visual>
    <collision>
      <origin
        xyz="0 0 0"
        rpy="0 0 0" />
      <geometry>
        <mesh
          filename="package://owr_bluetounge2_tf/meshes/front_left_wheel.STL" />
      </geometry>
    </collision>
  </link>
  <joint
    name="front_left_wheel_axel"
    type="continuous">
    <origin
      xyz="0.222263715818585 -0.0640000971993724 0"
      rpy="-2.51033723429329 -2.85119150511548E-14 -1.5707963267949" />
    <parent
      link="front_left_swerve_axel" />
    <child
      link="front_left_wheel" />
    <axis
      xyz="-1 0 0" />
  </joint>
  <link
    name="front_left_springs">
    <inertial>
      <origin
        xyz="-6.34422720663386E-07 0.0316858507419693 0.0150051402890246"
        rpy="0 0 0" />
      <mass
        value="0.07147587467537" />
      <inertia
        ixx="5.51663922922966E-05"
        ixy="-2.21242713266886E-08"
        ixz="2.57904841184568E-10"
        iyy="1.84882201034392E-05"
        iyz="7.80545040589428E-09"
        izz="3.91068937564176E-05" />
    </inertial>
    <visual>
      <origin
        xyz="0 0 0"
        rpy="0 0 0" />
      <geometry>
        <mesh
          filename="package://owr_bluetounge2_tf/meshes/front_left_springs.STL" />
      </geometry>
      <material
        name="">
        <color
          rgba="0.619607843137255 0.411764705882353 0.2 1" />
      </material>
    </visual>
    <collision>
      <origin
        xyz="0 0 0"
        rpy="0 0 0" />
      <geometry>
        <mesh
          filename="package://owr_bluetounge2_tf/meshes/front_left_springs.STL" />
      </geometry>
    </collision>
  </link>
  <joint
    name="front_left_spring_joint"
    type="fixed">
    <origin
      xyz="0.01502 0.090421258375798 0.123974013894054"
      rpy="-1.5707963267949 0.618421655113804 1.5707963267949" />
    <parent
      link="front_left_leg_base" />
    <child
      link="front_left_springs" />
    <axis
      xyz="0 0 0" />
  </joint>
  <link
    name="front_left_suspension">
    <inertial>
      <origin
        xyz="-0.0116167533649652 0.00132967364811817 0.0489941917398175"
        rpy="0 0 0" />
      <mass
        value="0.220510802496233" />
      <inertia
        ixx="0.000391574230086317"
        ixy="2.97557272333012E-06"
        ixz="-8.70096652989383E-06"
        iyy="0.00110669473892757"
        iyz="-1.33980482025628E-06"
        izz="0.000792853472152207" />
    </inertial>
    <visual>
      <origin
        xyz="0 0 0"
        rpy="0 0 0" />
      <geometry>
        <mesh
          filename="package://owr_bluetounge2_tf/meshes/front_left_suspension.STL" />
      </geometry>
      <material
        name="">
        <color
          rgba="0.101960784313725 0.101960784313725 0.101960784313725 1" />
      </material>
    </visual>
    <collision>
      <origin
        xyz="0 0 0"
        rpy="0 0 0" />
      <geometry>
        <mesh
          filename="package://owr_bluetounge2_tf/meshes/front_left_suspension.STL" />
      </geometry>
    </collision>
  </link>
  <joint
    name="front_left_suspension_joint"
    type="fixed">
    <origin
      xyz="0.00598346458625643 0.00807938385087792 -0.0330799999999998"
      rpy="0 0 -0.410314386932897" />
    <parent
      link="front_left_springs" />
    <child
      link="front_left_suspension" />
    <axis
      xyz="0 0 -1" />
  </joint>
  <link
    name="front_left_back_to_rover">
    <inertial>
      <origin
        xyz="1.1366576430083E-10 -0.0110053367071424 0.0171856026082578"
        rpy="0 0 0" />
      <mass
        value="0.108052469834526" />
      <inertia
        ixx="8.16035762454321E-05"
        ixy="-6.66003426805096E-13"
        ixz="-2.41891307909366E-13"
        iyy="4.43362317667963E-05"
        iyz="1.26211383778294E-05"
        izz="8.19573500045416E-05" />
    </inertial>
    <visual>
      <origin
        xyz="0 0 0"
        rpy="0 0 0" />
      <geometry>
        <mesh
          filename="package://owr_bluetounge2_tf/meshes/front_left_back_to_rover.STL" />
      </geometry>
      <material
        name="">
        <color
          rgba="0.101960784313725 0.101960784313725 0.101960784313725 1" />
      </material>
    </visual>
    <collision>
      <origin
        xyz="0 0 0"
        rpy="0 0 0" />
      <geometry>
        <mesh
          filename="package://owr_bluetounge2_tf/meshes/front_left_back_to_rover.STL" />
      </geometry>
    </collision>
  </link>
  <joint
    name="front_left_back_to_rover_joint"
    type="fixed">
    <origin
      xyz="-0.0907063945449771 0.0211184214377016 0.0481"
      rpy="1.7789035949758 1.5707963267949 0" />
    <parent
      link="front_left_suspension" />
    <child
      link="front_left_back_to_rover" />
    <axis
      xyz="1 0 0" />
  </joint>
  <link
    name="back_left_leg_base">
    <inertial>
      <origin
        xyz="0 0.00294015084396301 0.0195712415755609"
        rpy="0 0 0" />
      <mass
        value="0.0851788397766333" />
      <inertia
        ixx="4.20226124478787E-05"
        ixy="-5.18316819597836E-22"
        ixz="3.64385312888067E-21"
        iyy="3.11208969345463E-05"
        iyz="-7.80560663932145E-07"
        izz="4.60535086117172E-05" />
    </inertial>
    <visual>
      <origin
        xyz="0 0 0"
        rpy="0 0 0" />
      <geometry>
        <mesh
          filename="package://owr_bluetounge2_tf/meshes/back_left_leg_base.STL" />
      </geometry>
      <material
        name="">
        <color
          rgba="0.101960784313725 0.101960784313725 0.101960784313725 1" />
      </material>
    </visual>
    <collision>
      <origin
        xyz="0 0 0"
        rpy="0 0 0" />
      <geometry>
        <mesh
          filename="package://owr_bluetounge2_tf/meshes/back_left_leg_base.STL" />
      </geometry>
    </collision>
  </link>
  <joint
    name="back_left_leg_base_joint"
    type="fixed">
    <origin
      xyz="-0.27095694131393 0.22581334799853 0.106000000000001"
      rpy="3.14159265358979 -7.45286116330805E-17 3.14159265358979" />
    <parent
      link="chassis" />
    <child
      link="back_left_leg_base" />
    <axis
      xyz="0 0 0" />
  </joint>
  <link
    name="back_left_leg_top">
    <inertial>
      <origin
        xyz="-0.0112199907904004 0.000771963062171949 0.0486489076535467"
        rpy="0 0 0" />
      <mass
        value="0.228308259818507" />
      <inertia
        ixx="0.000397132796967211"
        ixy="1.54692794789757E-06"
        ixz="-9.58555872945969E-06"
        iyy="0.00111126093322185"
        iyz="-9.64819056593276E-08"
        izz="0.000796144386061546" />
    </inertial>
    <visual>
      <origin
        xyz="0 0 0"
        rpy="0 0 0" />
      <geometry>
        <mesh
          filename="package://owr_bluetounge2_tf/meshes/back_left_leg_top.STL" />
      </geometry>
      <material
        name="">
        <color
          rgba="0.101960784313725 0.101960784313725 0.101960784313725 1" />
      </material>
    </visual>
    <collision>
      <origin
        xyz="0 0 0"
        rpy="0 0 0" />
      <geometry>
        <mesh
          filename="package://owr_bluetounge2_tf/meshes/back_left_leg_top.STL" />
      </geometry>
    </collision>
  </link>
  <joint
    name="back_left_leg_top_suspension"
    type="fixed">
    <origin
      xyz="0.0480999999999996 0.0906125308820751 0.00192206350156069"
      rpy="-1.5707963267949 0.208107268180907 1.5707963267949" />
    <parent
      link="back_left_leg_base" />
    <child
      link="back_left_leg_top" />
    <axis
      xyz="0 0 -1" />
  </joint>
  <link
    name="back_left_swerve_top">
    <inertial>
      <origin
        xyz="0.0190496508359126 0.0181018716824016 -0.0350197808493304"
        rpy="0 0 0" />
      <mass
        value="0.101733926431314" />
      <inertia
        ixx="0.000296891505221715"
        ixy="-6.18972323817749E-10"
        ixz="-2.3991472275602E-09"
        iyy="0.000370577039007181"
        iyz="7.87905207653263E-07"
        izz="0.000108204880075919" />
    </inertial>
    <visual>
      <origin
        xyz="0 0 0"
        rpy="0 0 0" />
      <geometry>
        <mesh
          filename="package://owr_bluetounge2_tf/meshes/back_left_swerve_top.STL" />
      </geometry>
      <material
        name="">
        <color
          rgba="0.898039215686275 0.92156862745098 0.929411764705882 1" />
      </material>
    </visual>
    <collision>
      <origin
        xyz="0 0 0"
        rpy="0 0 0" />
      <geometry>
        <mesh
          filename="package://owr_bluetounge2_tf/meshes/back_left_swerve_top.STL" />
      </geometry>
    </collision>
  </link>
  <joint
    name="back_left_swerve_to_suspension"
    type="fixed">
    <origin
      xyz="0.102203082302949 -0.0225748614789264 0.0671499999999996"
      rpy="-1.34 1.5707963267949 0" />
    <parent
      link="back_left_leg_top" />
    <child
      link="back_left_swerve_top" />
    <axis
      xyz="-1 0 0" />
  </joint>
  <link
    name="back_left_swerve_axel">
    <inertial>
      <origin
        xyz="7.19512227576047E-11 -0.0498207928462409 -0.0423647942792511"
        rpy="0 0 0" />
      <mass
        value="2.34386977405423" />
      <inertia
        ixx="0.0168346139802583"
        ixy="8.60481792048194E-10"
        ixz="2.78266273006722E-11"
        iyy="0.00668199276805567"
        iyz="-0.00185588353063867"
        izz="0.0115644107590486" />
    </inertial>
    <visual>
      <origin
        xyz="0 0 0"
        rpy="0 0 0" />
      <geometry>
        <mesh
          filename="package://owr_bluetounge2_tf/meshes/back_left_swerve_axel.STL" />
      </geometry>
      <material
        name="">
        <color
          rgba="0.898039215686275 0.92156862745098 0.929411764705882 1" />
      </material>
    </visual>
    <collision>
      <origin
        xyz="0 0 0"
        rpy="0 0 0" />
      <geometry>
        <mesh
          filename="package://owr_bluetounge2_tf/meshes/back_left_swerve_axel.STL" />
      </geometry>
    </collision>
  </link>
  <joint
    name="back_left_swerve"
    type="continuous">
    <origin
      xyz="0.01905 0.01905 -0.166471215818396"
      rpy="6.88199027360824E-16 -1.24047364670461E-16 0.0539793695678587" />
    <parent
      link="back_left_swerve_top" />
    <child
      link="back_left_swerve_axel" />
    <axis
      xyz="0 0 1" />
  </joint>
  <link
    name="back_left_wheel">
    <inertial>
      <origin
        xyz="-0.0663813744814109 -1.95940016275431E-05 -2.22091400667868E-05"
        rpy="0 0 0" />
      <mass
        value="2.15472811624945" />
      <inertia
        ixx="0.0180021390861626"
        ixy="6.42530610878774E-07"
        ixz="7.28286779060159E-07"
        iyy="0.0154652772226983"
        iyz="-1.72296508623235E-07"
        izz="0.0154653205064802" />
    </inertial>
    <visual>
      <origin
        xyz="0 0 0"
        rpy="0 0 0" />
      <geometry>
        <mesh
          filename="package://owr_bluetounge2_tf/meshes/back_left_wheel.STL" />
      </geometry>
      <material
        name="">
        <color
          rgba="0.294117647058824 0.294117647058824 0.294117647058824 1" />
      </material>
    </visual>
    <collision>
      <origin
        xyz="0 0 0"
        rpy="0 0 0" />
      <geometry>
        <mesh
          filename="package://owr_bluetounge2_tf/meshes/back_left_wheel.STL" />
      </geometry>
    </collision>
  </link>
  <joint
    name="back_left_wheel_axel"
    type="continuous">
    <origin
      xyz="0 0.0640000971993742 -0.182000000000186"
      rpy="2.20205174609139 7.70217223333702E-16 1.57079632679491" />
    <parent
      link="back_left_swerve_axel" />
    <child
      link="back_left_wheel" />
    <axis
      xyz="-1 0 0" />
  </joint>
  <link
    name="back_left_springs">
    <inertial>
      <origin
        xyz="-6.30600931861292E-06 0.0148626589856348 0.0582344880671569"
        rpy="0 0 0" />
      <mass
        value="0.0721610801823068" />
      <inertia
        ixx="5.76521055619966E-05"
        ixy="6.34071281322869E-09"
        ixz="4.57978611154678E-08"
        iyy="4.14371498185916E-05"
        iyz="5.86483957747543E-07"
        izz="1.86743574660707E-05" />
    </inertial>
    <visual>
      <origin
        xyz="0 0 0"
        rpy="0 0 0" />
      <geometry>
        <mesh
          filename="package://owr_bluetounge2_tf/meshes/back_left_springs.STL" />
      </geometry>
      <material
        name="">
        <color
          rgba="0.792156862745098 0.819607843137255 0.933333333333333 1" />
      </material>
    </visual>
    <collision>
      <origin
        xyz="0 0 0"
        rpy="0 0 0" />
      <geometry>
        <mesh
          filename="package://owr_bluetounge2_tf/meshes/back_left_springs.STL" />
      </geometry>
    </collision>
  </link>
  <joint
    name="back_left_spring_joint"
    type="fixed">
    <origin
      xyz="0.01502 0.0379687078450422 0.0502559265692599"
      rpy="-1.06451592460411E-16 0.618421655113802 1.5707963267949" />
    <parent
      link="back_left_leg_base" />
    <child
      link="back_left_springs" />
    <axis
      xyz="0 0 0" />
  </joint>
  <link
    name="back_left_suspension">
    <inertial>
      <origin
        xyz="-0.00993956116482878 -0.0165027609959398 0.000651802123213252"
        rpy="0 0 0" />
      <mass
        value="0.198286979880301" />
      <inertia
        ixx="0.000997362802202282"
        ixy="-0.000193403615901097"
        ixz="2.74722792889628E-06"
        iyy="0.000437847659019844"
        iyz="-8.98211930016478E-06"
        izz="0.000747942603429789" />
    </inertial>
    <visual>
      <origin
        xyz="0 0 0"
        rpy="0 0 0" />
      <geometry>
        <mesh
          filename="package://owr_bluetounge2_tf/meshes/back_left_suspension.STL" />
      </geometry>
      <material
        name="">
        <color
          rgba="0.894117647058823 0.913725490196078 0.929411764705882 1" />
      </material>
    </visual>
    <collision>
      <origin
        xyz="0 0 0"
        rpy="0 0 0" />
      <geometry>
        <mesh
          filename="package://owr_bluetounge2_tf/meshes/back_left_suspension.STL" />
      </geometry>
    </collision>
  </link>
  <joint
    name="back_left_suspension_joint"
    type="fixed">
    <origin
      xyz="0 0.0149999999999999 0.09615"
      rpy="1.5707963267949 -0.855968458217554 3.14159265358979" />
    <parent
      link="back_left_springs" />
    <child
      link="back_left_suspension" />
    <axis
      xyz="0 0 1" />
  </joint>
  <link
    name="back_left_to_rover">
    <inertial>
      <origin
        xyz="1.13665632461846E-10 -0.0110053367071424 0.0171856026082578"
        rpy="0 0 0" />
      <mass
        value="0.108052469834526" />
      <inertia
        ixx="8.1603576245432E-05"
        ixy="-6.66003538809094E-13"
        ixz="-2.41891348352757E-13"
        iyy="4.43362317667962E-05"
        iyz="1.26211383778294E-05"
        izz="8.19573500045416E-05" />
    </inertial>
    <visual>
      <origin
        xyz="0 0 0"
        rpy="0 0 0" />
      <geometry>
        <mesh
          filename="package://owr_bluetounge2_tf/meshes/back_left_to_rover.STL" />
      </geometry>
      <material
        name="">
        <color
          rgba="0.101960784313725 0.101960784313725 0.101960784313725 1" />
      </material>
    </visual>
    <collision>
      <origin
        xyz="0 0 0"
        rpy="0 0 0" />
      <geometry>
        <mesh
          filename="package://owr_bluetounge2_tf/meshes/back_left_to_rover.STL" />
      </geometry>
    </collision>
  </link>
  <joint
    name="back_left_to_rover_joint"
    type="fixed">
    <origin
      xyz="-0.0072603045458083 -0.0973626127237505 2.00000000003531E-05"
      rpy="0.0964062134635395 1.5707963267949 0" />
    <parent
      link="back_left_suspension" />
    <child
      link="back_left_to_rover" />
    <axis
      xyz="1 0 0" />
  </joint>
  <link
    name="front_right_leg_base">
    <inertial>
      <origin
        xyz="3.46944695195361E-18 0.00294015084396307 0.0195712415755609"
        rpy="0 0 0" />
      <mass
        value="0.0851788397766331" />
      <inertia
        ixx="4.20226124478787E-05"
        ixy="9.19859924786697E-22"
        ixz="8.99054224481237E-22"
        iyy="3.11208969345462E-05"
        iyz="-7.80560663932162E-07"
        izz="4.60535086117171E-05" />
    </inertial>
    <visual>
      <origin
        xyz="0 0 0"
        rpy="0 0 0" />
      <geometry>
        <mesh
          filename="package://owr_bluetounge2_tf/meshes/front_right_leg_base.STL" />
      </geometry>
      <material
        name="">
        <color
          rgba="0.101960784313725 0.101960784313725 0.101960784313725 1" />
      </material>
    </visual>
    <collision>
      <origin
        xyz="0 0 0"
        rpy="0 0 0" />
      <geometry>
        <mesh
          filename="package://owr_bluetounge2_tf/meshes/front_right_leg_base.STL" />
      </geometry>
    </collision>
  </link>
  <joint
    name="front_right_leg_base_joint"
    type="fixed">
    <origin
      xyz="0.27104305868607 -0.22418665200147 0.106000000000001"
      rpy="3.14159265358979 -1.22075621657598E-17 -7.14214183116779E-19" />
    <parent
      link="chassis" />
    <child
      link="front_right_leg_base" />
    <axis
      xyz="0 0 0" />
  </joint>
  <link
    name="front_right_leg_top">
    <inertial>
      <origin
        xyz="0.0762803933912035 0.034376092346453 0.000771578880568294"
        rpy="0 0 0" />
      <mass
        value="0.228308259818507" />
      <inertia
        ixx="0.00039713279696721"
        ixy="9.58555872946049E-06"
        ixz="1.54692794789606E-06"
        iyy="0.000796144386061545"
        iyz="9.6481905659539E-08"
        izz="0.00111126093322185" />
    </inertial>
    <visual>
      <origin
        xyz="0 0 0"
        rpy="0 0 0" />
      <geometry>
        <mesh
          filename="package://owr_bluetounge2_tf/meshes/front_right_leg_top.STL" />
      </geometry>
      <material
        name="">
        <color
          rgba="0.898039215686275 0.92156862745098 0.929411764705882 1" />
      </material>
    </visual>
    <collision>
      <origin
        xyz="0 0 0"
        rpy="0 0 0" />
      <geometry>
        <mesh
          filename="package://owr_bluetounge2_tf/meshes/front_right_leg_top.STL" />
      </geometry>
    </collision>
  </link>
  <joint
    name="front_right_leg_top_suspension"
    type="fixed">
    <origin
      xyz="-0.0349249999999999 0.005 0.02"
      rpy="3.14159265358979 0.208107268180909 1.5707963267949" />
    <parent
      link="front_right_leg_base" />
    <child
      link="front_right_leg_top" />
    <axis
      xyz="0 1 0" />
  </joint>
  <link
    name="front_right_swerve_top">
    <inertial>
      <origin
        xyz="-0.000934279116028947 -0.00762686801808265 -0.0290327080939286"
        rpy="0 0 0" />
      <mass
        value="0.0699119426149696" />
      <inertia
        ixx="0.000242162498858513"
        ixy="1.03556231285493E-07"
        ixz="-6.18537934450094E-10"
        iyy="7.13785757451374E-05"
        iyz="-2.73863248717861E-09"
        izz="0.000198899617450818" />
    </inertial>
    <visual>
      <origin
        xyz="0 0 0"
        rpy="0 0 0" />
      <geometry>
        <mesh
          filename="package://owr_bluetounge2_tf/meshes/front_right_swerve_top.STL" />
      </geometry>
      <material
        name="">
        <color
          rgba="0.898039215686275 0.92156862745098 0.929411764705882 1" />
      </material>
    </visual>
    <collision>
      <origin
        xyz="0 0 0"
        rpy="0 0 0" />
      <geometry>
        <mesh
          filename="package://owr_bluetounge2_tf/meshes/front_right_swerve_top.STL" />
      </geometry>
    </collision>
  </link>
  <joint
    name="front_right_swerve_to_suspension"
    type="fixed">
    <origin
      xyz="0.163430315051558 0.0639571999999999 -0.0547921125749097"
      rpy="1.5707963267949 -0.208107268180909 3.14159265358979" />
    <parent
      link="front_right_leg_top" />
    <child
      link="front_right_swerve_top" />
    <axis
      xyz="0 0 -1" />
  </joint>
  <link
    name="front_right_swerve_axel">
    <inertial>
      <origin
        xyz="1.48448894354142E-06 -0.0478348037669294 -0.0419346754576931"
        rpy="0 0 0" />
      <mass
        value="2.39661383258398" />
      <inertia
        ixx="0.0175344222264242"
        ixy="8.45593804007453E-08"
        ixz="1.66156894586256E-07"
        iyy="0.00687378211776298"
        iyz="-0.00192388332949361"
        izz="0.0120933679250739" />
    </inertial>
    <visual>
      <origin
        xyz="0 0 0"
        rpy="0 0 0" />
      <geometry>
        <mesh
          filename="package://owr_bluetounge2_tf/meshes/front_right_swerve_axel.STL" />
      </geometry>
      <material
        name="">
        <color
          rgba="0.898039215686275 0.92156862745098 0.929411764705882 1" />
      </material>
    </visual>
    <collision>
      <origin
        xyz="0 0 0"
        rpy="0 0 0" />
      <geometry>
        <mesh
          filename="package://owr_bluetounge2_tf/meshes/front_right_swerve_axel.STL" />
      </geometry>
    </collision>
  </link>
  <joint
    name="front_right_swerve"
    type="continuous">
    <origin
      xyz="0 -0.129521215818398 -0.0290322"
      rpy="-1.5707963267949 -1.51681695722704 0" />
    <parent
      link="front_right_swerve_top" />
    <child
      link="front_right_swerve_axel" />
    <axis
      xyz="0 0 1" />
  </joint>
  <link
    name="front_right_wheel">
    <inertial>
      <origin
        xyz="-0.0663813744814108 -1.95940016275431E-05 -2.2209140066648E-05"
        rpy="0 0 0" />
      <mass
        value="2.15472811624945" />
      <inertia
        ixx="0.0180021390861626"
        ixy="6.42530610880075E-07"
        ixz="7.28286779065959E-07"
        iyy="0.0154652772226982"
        iyz="-1.72296508627543E-07"
        izz="0.0154653205064802" />
    </inertial>
    <visual>
      <origin
        xyz="0 0 0"
        rpy="0 0 0" />
      <geometry>
        <mesh
          filename="package://owr_bluetounge2_tf/meshes/front_right_wheel.STL" />
      </geometry>
      <material
        name="">
        <color
          rgba="0.294117647058824 0.294117647058824 0.294117647058824 1" />
      </material>
    </visual>
    <collision>
      <origin
        xyz="0 0 0"
        rpy="0 0 0" />
      <geometry>
        <mesh
          filename="package://owr_bluetounge2_tf/meshes/front_right_wheel.STL" />
      </geometry>
    </collision>
  </link>
  <joint
    name="front_right_wheel_axel"
    type="continuous">
    <origin
      xyz="0 0.0640000971993744 -0.182000000000186"
      rpy="2.20205174609138 1.93248195223816E-15 1.57079632679491" />
    <parent
      link="front_right_swerve_axel" />
    <child
      link="front_right_wheel" />
    <axis
      xyz="-1 0 0" />
  </joint>
  <link
    name="front_right_springs">
    <inertial>
      <origin
        xyz="-1.18708999517214E-05 0.0327836528481927 0.0150050435880243"
        rpy="0 0 0" />
      <mass
        value="0.0728462856892433" />
      <inertia
        ixx="6.00970581301089E-05"
        ixy="-6.9026422115648E-08"
        ixz="2.62033197716698E-10"
        iyy="1.88632088165928E-05"
        iyz="7.4021106070601E-09"
        izz="4.37239220811648E-05" />
    </inertial>
    <visual>
      <origin
        xyz="0 0 0"
        rpy="0 0 0" />
      <geometry>
        <mesh
          filename="package://owr_bluetounge2_tf/meshes/front_right_springs.STL" />
      </geometry>
      <material
        name="">
        <color
          rgba="0.619607843137255 0.411764705882353 0.2 1" />
      </material>
    </visual>
    <collision>
      <origin
        xyz="0 0 0"
        rpy="0 0 0" />
      <geometry>
        <mesh
          filename="package://owr_bluetounge2_tf/meshes/front_right_springs.STL" />
      </geometry>
    </collision>
  </link>
  <joint
    name="front_right_spring_joint"
    type="fixed">
    <origin
      xyz="0.01502 0.090421258375798 0.123974013894054"
      rpy="-1.5707963267949 0.618421655113805 1.5707963267949" />
    <parent
      link="front_right_leg_base" />
    <child
      link="front_right_springs" />
    <axis
      xyz="0 0 0" />
  </joint>
  <link
    name="front_right_suspension">
    <inertial>
      <origin
        xyz="-0.00603449184340332 0.00108839617956266 0.0486309703678901"
        rpy="0 0 0" />
      <mass
        value="0.235941857530821" />
      <inertia
        ixx="0.000413465403175823"
        ixy="1.11910137739801E-06"
        ixz="-1.02355557397758E-05"
        iyy="0.0012486554203498"
        iyz="-1.35461377079528E-07"
        izz="0.000916060072494879" />
    </inertial>
    <visual>
      <origin
        xyz="0 0 0"
        rpy="0 0 0" />
      <geometry>
        <mesh
          filename="package://owr_bluetounge2_tf/meshes/front_right_suspension.STL" />
      </geometry>
      <material
        name="">
        <color
          rgba="0.101960784313725 0.101960784313725 0.101960784313725 1" />
      </material>
    </visual>
    <collision>
      <origin
        xyz="0 0 0"
        rpy="0 0 0" />
      <geometry>
        <mesh
          filename="package://owr_bluetounge2_tf/meshes/front_right_suspension.STL" />
      </geometry>
    </collision>
  </link>
  <joint
    name="front_right_suspension_joint"
    type="fixed">
    <origin
      xyz="0.00598346458625632 0.00807938385087792 -0.0330799999999998"
      rpy="0 -3.46944695195361E-16 -0.410314386932897" />
    <parent
      link="front_right_springs" />
    <child
      link="front_right_suspension" />
    <axis
      xyz="0 0 -1" />
  </joint>
  <link
    name="front_right_to_rover">
    <inertial>
      <origin
        xyz="1.13665753892489E-10 -0.0110053367071423 0.0171856026082578"
        rpy="0 0 0" />
      <mass
        value="0.108052469834526" />
      <inertia
        ixx="8.16035762454321E-05"
        ixy="-6.66003441134059E-13"
        ixz="-2.41891310406903E-13"
        iyy="4.43362317667963E-05"
        iyz="1.26211383778295E-05"
        izz="8.19573500045416E-05" />
    </inertial>
    <visual>
      <origin
        xyz="0 0 0"
        rpy="0 0 0" />
      <geometry>
        <mesh
          filename="package://owr_bluetounge2_tf/meshes/front_right_to_rover.STL" />
      </geometry>
      <material
        name="">
        <color
          rgba="0.101960784313725 0.101960784313725 0.101960784313725 1" />
      </material>
    </visual>
    <collision>
      <origin
        xyz="0 0 0"
        rpy="0 0 0" />
      <geometry>
        <mesh
          filename="package://owr_bluetounge2_tf/meshes/front_right_to_rover.STL" />
      </geometry>
    </collision>
  </link>
  <joint
    name="front_right_to_rover_joint"
    type="fixed">
    <origin
      xyz="-0.0907063945449771 0.0211184214377016 0.0481000000000001"
      rpy="1.7789035949758 1.5707963267949 0" />
    <parent
      link="front_right_suspension" />
    <child
      link="front_right_to_rover" />
    <axis
      xyz="1 0 0" />
  </joint>
  <link
    name="back_right_leg_base">
    <inertial>
      <origin
        xyz="0 0.00294015084396307 0.0195712415755609"
        rpy="0 0 0" />
      <mass
        value="0.0851788397766333" />
      <inertia
        ixx="4.20226124478787E-05"
        ixy="1.84693696823693E-21"
        ixz="4.5401604138119E-21"
        iyy="3.11208969345462E-05"
        iyz="-7.80560663932158E-07"
        izz="4.60535086117172E-05" />
    </inertial>
    <visual>
      <origin
        xyz="0 0 0"
        rpy="0 0 0" />
      <geometry>
        <mesh
          filename="package://owr_bluetounge2_tf/meshes/back_right_leg_base.STL" />
      </geometry>
      <material
        name="">
        <color
          rgba="0.101960784313725 0.101960784313725 0.101960784313725 1" />
      </material>
    </visual>
    <collision>
      <origin
        xyz="0 0 0"
        rpy="0 0 0" />
      <geometry>
        <mesh
          filename="package://owr_bluetounge2_tf/meshes/back_right_leg_base.STL" />
      </geometry>
    </collision>
  </link>
  <joint
    name="back_right_leg_base_joint"
    type="fixed">
    <origin
      xyz="-0.27095694131393 -0.22418665200147 0.106000000000001"
      rpy="3.14159265358979 -1.22075621657598E-17 -7.14214183116779E-19" />
    <parent
      link="chassis" />
    <child
      link="back_right_leg_base" />
    <axis
      xyz="0 0 0" />
  </joint>
  <link
    name="back_right_leg_top">
    <inertial>
      <origin
        xyz="-0.0112199907904005 -0.000771963062172087 0.0475510923464529"
        rpy="0 0 0" />
      <mass
        value="0.228308259818507" />
      <inertia
        ixx="0.000397132796967212"
        ixy="-1.54692794789702E-06"
        ixz="9.58555872945987E-06"
        iyy="0.00111126093322186"
        iyz="-9.64819056594623E-08"
        izz="0.000796144386061546" />
    </inertial>
    <visual>
      <origin
        xyz="0 0 0"
        rpy="0 0 0" />
      <geometry>
        <mesh
          filename="package://owr_bluetounge2_tf/meshes/back_right_leg_top.STL" />
      </geometry>
      <material
        name="">
        <color
          rgba="0.101960784313725 0.101960784313725 0.101960784313725 1" />
      </material>
    </visual>
    <collision>
      <origin
        xyz="0 0 0"
        rpy="0 0 0" />
      <geometry>
        <mesh
          filename="package://owr_bluetounge2_tf/meshes/back_right_leg_top.STL" />
      </geometry>
    </collision>
  </link>
  <joint
    name="back_right_leg_top_suspension"
    type="fixed">
    <origin
      xyz="-0.0480999999999999 0.0906125308820751 0.00192206350156076"
      rpy="1.5707963267949 0.208107268180907 1.5707963267949" />
    <parent
      link="back_right_leg_base" />
    <child
      link="back_right_leg_top" />
    <axis
      xyz="0 0 1" />
  </joint>
  <link
    name="back_right_swerve_top">
    <inertial>
      <origin
        xyz="0.0190495417284672 0.0180064663449653 -0.0493202140614411"
        rpy="0 0 0" />
      <mass
        value="0.0775126339604044" />
      <inertia
        ixx="0.000216953742157336"
        ixy="-6.22418856352744E-10"
        ixz="-2.90712483624388E-09"
        iyy="0.00026394395553722"
        iyz="4.7303974584288E-07"
        izz="7.73969347715285E-05" />
    </inertial>
    <visual>
      <origin
        xyz="0 0 0"
        rpy="0 0 0" />
      <geometry>
        <mesh
          filename="package://owr_bluetounge2_tf/meshes/back_right_swerve_top.STL" />
      </geometry>
      <material
        name="">
        <color
          rgba="0.898039215686275 0.92156862745098 0.929411764705882 1" />
      </material>
    </visual>
    <collision>
      <origin
        xyz="0 0 0"
        rpy="0 0 0" />
      <geometry>
        <mesh
          filename="package://owr_bluetounge2_tf/meshes/back_right_swerve_top.STL" />
      </geometry>
    </collision>
  </link>
  <joint
    name="back_right_swerve_to_suspension"
    type="fixed">
    <origin
      xyz="0.102203082302949 0.0225748614789264 0.0290499999999999"
      rpy="1.72268905861399 -1.5707963267949 0" />
    <parent
      link="back_right_leg_top" />
    <child
      link="back_right_swerve_top" />
    <axis
      xyz="-1 0 0" />
  </joint>
  <link
    name="back_right_swerve_axel">
    <inertial>
      <origin
        xyz="7.19512227576047E-11 -0.0498207928462409 -0.0423647942792511"
        rpy="0 0 0" />
      <mass
        value="2.34386977405423" />
      <inertia
        ixx="0.0168346139802583"
        ixy="8.60481792048194E-10"
        ixz="2.78266273006722E-11"
        iyy="0.00668199276805567"
        iyz="-0.00185588353063867"
        izz="0.0115644107590486" />
    </inertial>
    <visual>
      <origin
        xyz="0 0 0"
        rpy="0 0 0" />
      <geometry>
        <mesh
          filename="package://owr_bluetounge2_tf/meshes/back_left_swerve_axel.STL" />
      </geometry>
      <material
        name="">
        <color
          rgba="0.898039215686275 0.92156862745098 0.929411764705882 1" />
      </material>
    </visual>
    <collision>
      <origin
        xyz="0 0 0"
        rpy="0 0 0" />
      <geometry>
        <mesh
          filename="package://owr_bluetounge2_tf/meshes/back_left_swerve_axel.STL" />
      </geometry>
    </collision>
  </link>
  <joint
    name="back_right_swerve"
    type="continuous">
    <origin
      xyz="0.01905 0.01905 -0.166471215818396"
      rpy="6.88199027360824E-16 -1.24047364670461E-16 0.0539793695678587" />
    <parent
      link="back_right_swerve_top" />
    <child
      link="back_right_swerve_axel" />
    <axis
      xyz="0 0 -1" />
  </joint>
  <link
    name="back_right_wheel">
    <inertial>
      <origin
        xyz="-0.0663813744814109 -1.95940016275431E-05 -2.22091400667868E-05"
        rpy="0 0 0" />
      <mass
        value="2.15472811624945" />
      <inertia
        ixx="0.0180021390861626"
        ixy="6.42530610878774E-07"
        ixz="7.28286779060159E-07"
        iyy="0.0154652772226983"
        iyz="-1.72296508623235E-07"
        izz="0.0154653205064802" />
    </inertial>
    <visual>
      <origin
        xyz="0 0 0"
        rpy="0 0 0" />
      <geometry>
        <mesh
          filename="package://owr_bluetounge2_tf/meshes/back_left_wheel.STL" />
      </geometry>
      <material
        name="">
        <color
          rgba="0.294117647058824 0.294117647058824 0.294117647058824 1" />
      </material>
    </visual>
    <collision>
      <origin
        xyz="0 0 0"
        rpy="0 0 0" />
      <geometry>
        <mesh
          filename="package://owr_bluetounge2_tf/meshes/back_left_wheel.STL" />
      </geometry>
    </collision>
  </link>
  <joint
    name="back_right_wheel_axel"
    type="continuous">
    <origin
      xyz="0 0.0640000971993742 -0.182000000000186"
      rpy="2.20205174609139 7.70217223333702E-16 1.57079632679491" />
    <parent
      link="back_right_swerve_axel" />
    <child
      link="back_right_wheel" />
    <axis
      xyz="-1 0 0" />
  </joint>
  <link
    name="back_right_springs">
    <inertial>
      <origin
        xyz="-1.18708999515826E-05 -0.0149949564119756 0.0576907991037673"
        rpy="0 0 0" />
      <mass
        value="0.0728462856892432" />
      <inertia
        ixx="6.00970581301089E-05"
        ixy="2.62033197700532E-10"
        ixz="6.9026422115703E-08"
        iyy="4.37239220811648E-05"
        iyz="-7.40211060711539E-09"
        izz="1.88632088165929E-05" />
    </inertial>
    <visual>
      <origin
        xyz="0 0 0"
        rpy="0 0 0" />
      <geometry>
        <mesh
          filename="package://owr_bluetounge2_tf/meshes/back_right_springs.STL" />
      </geometry>
      <material
        name="">
        <color
          rgba="0.792156862745098 0.819607843137255 0.933333333333333 1" />
      </material>
    </visual>
    <collision>
      <origin
        xyz="0 0 0"
        rpy="0 0 0" />
      <geometry>
        <mesh
          filename="package://owr_bluetounge2_tf/meshes/back_right_springs.STL" />
      </geometry>
    </collision>
  </link>
  <joint
    name="back_right_spring_joint"
    type="fixed">
    <origin
      xyz="-0.01498 0.0379687078450422 0.0502559265692599"
      rpy="0 0.618421655113803 1.5707963267949" />
    <parent
      link="back_right_leg_base" />
    <child
      link="back_right_springs" />
    <axis
      xyz="0 0 0" />
  </joint>
  <link
    name="back_right_suspension">
    <inertial>
      <origin
        xyz="-0.0114902738387502 -0.00115188134063246 0.047538058612584"
        rpy="0 0 0" />
      <mass
        value="0.222938081620854" />
      <inertia
        ixx="0.000394551830605388"
        ixy="-2.52013646251625E-06"
        ixz="9.55206554700924E-06"
        iyy="0.00110935612499406"
        iyz="-1.43414679652446E-07"
        izz="0.000793879634967821" />
    </inertial>
    <visual>
      <origin
        xyz="0 0 0"
        rpy="0 0 0" />
      <geometry>
        <mesh
          filename="package://owr_bluetounge2_tf/meshes/back_right_suspension.STL" />
      </geometry>
      <material
        name="">
        <color
          rgba="0.101960784313725 0.101960784313725 0.101960784313725 1" />
      </material>
    </visual>
    <collision>
      <origin
        xyz="0 0 0"
        rpy="0 0 0" />
      <geometry>
        <mesh
          filename="package://owr_bluetounge2_tf/meshes/back_right_suspension.STL" />
      </geometry>
    </collision>
  </link>
  <joint
    name="back_right_suspension_joint"
    type="fixed">
    <origin
      xyz="0.00598346458625637 0.03312 0.082395068101082"
      rpy="1.5707963267949 -0.410314386932896 0" />
    <parent
      link="back_right_springs" />
    <child
      link="back_right_suspension" />
    <axis
      xyz="0 0 1" />
  </joint>
  <link
    name="back_right_to_rover">
    <inertial>
      <origin
        xyz="1.13665743484148E-10 -0.0110053367071424 0.0171856026082578"
        rpy="0 0 0" />
      <mass
        value="0.108052469834526" />
      <inertia
        ixx="8.16035762454319E-05"
        ixy="-6.6600337596301E-13"
        ixz="-2.41891298443816E-13"
        iyy="4.43362317667963E-05"
        iyz="1.26211383778294E-05"
        izz="8.19573500045415E-05" />
    </inertial>
    <visual>
      <origin
        xyz="0 0 0"
        rpy="0 0 0" />
      <geometry>
        <mesh
          filename="package://owr_bluetounge2_tf/meshes/back_right_to_rover.STL" />
      </geometry>
      <material
        name="">
        <color
          rgba="0.101960784313725 0.101960784313725 0.101960784313725 1" />
      </material>
    </visual>
    <collision>
      <origin
        xyz="0 0 0"
        rpy="0 0 0" />
      <geometry>
        <mesh
          filename="package://owr_bluetounge2_tf/meshes/back_right_to_rover.STL" />
      </geometry>
    </collision>
  </link>
  <joint
    name="back_right_to_rover_joint"
    type="fixed">
    <origin
      xyz="-0.090706394544977 -0.0211184214377016 0.0480999999999998"
      rpy="1.7789035949758 -1.5707963267949 0" />
    <parent
      link="back_right_suspension" />
    <child
      link="back_right_to_rover" />
    <axis
      xyz="1 0 0" />
  </joint>
  <link
    name="arm_base">
    <inertial>
      <origin
        xyz="-0.00577800660165687 4.17841682295306E-05 0.136866703717242"
        rpy="0 0 0" />
      <mass
        value="1.97025617277148" />
      <inertia
        ixx="0.0111631361256287"
        ixy="3.89200111286753E-07"
        ixz="-0.00169119197006603"
        iyy="0.0116407591577356"
        iyz="-6.56640255781496E-07"
        izz="0.0127422376535343" />
    </inertial>
    <visual>
      <origin
        xyz="0 0 0"
        rpy="0 0 0" />
      <geometry>
        <mesh
          filename="package://owr_bluetounge2_tf/meshes/arm_base.STL" />
      </geometry>
      <material
        name="">
        <color
          rgba="1 1 1 1" />
      </material>
    </visual>
    <collision>
      <origin
        xyz="0 0 0"
        rpy="0 0 0" />
      <geometry>
        <mesh
          filename="package://owr_bluetounge2_tf/meshes/arm_base.STL" />
      </geometry>
    </collision>
  </link>
  <joint
    name="arm_base_rotation"
    type="fixed">
    <origin
      xyz="0.172554697757751 -0.0724869639786827 0"
      rpy="5.78193091528853E-16 -1.03121787249516E-15 -0.0880750381353883" />
    <parent
      link="chassis" />
    <child
      link="arm_base" />
    <axis
      xyz="0 0 -1" />
  </joint>
  <link
    name="arm_top_actuator_base">
    <inertial>
      <origin
        xyz="-0.0199928804547402 0.106614805768208 0.0339996193086286"
        rpy="0 0 0" />
      <mass
        value="0.505108099872299" />
      <inertia
        ixx="0.0035033185257942"
        ixy="-0.00125167584583982"
        ixz="2.41541101410423E-10"
        iyy="0.000780139366796628"
        iyz="-1.03659650314673E-09"
        izz="0.00415524009479793" />
    </inertial>
    <visual>
      <origin
        xyz="0 0 0"
        rpy="0 0 0" />
      <geometry>
        <mesh
          filename="package://owr_bluetounge2_tf/meshes/arm_top_actuator_base.STL" />
      </geometry>
      <material
        name="">
        <color
          rgba="1 1 1 1" />
      </material>
    </visual>
    <collision>
      <origin
        xyz="0 0 0"
        rpy="0 0 0" />
      <geometry>
        <mesh
          filename="package://owr_bluetounge2_tf/meshes/arm_top_actuator_base.STL" />
      </geometry>
    </collision>
  </link>
  <joint
    name="arm_top_actuator_rotate"
    type="fixed">
    <origin
      xyz="-0.0898397083141685 -0.0340000000000132 0.333283716713238"
      rpy="1.5707963267949 -9.83199358550766E-16 -3.14159265358966" />
    <parent
      link="arm_base" />
    <child
      link="arm_top_actuator_base" />
    <axis
      xyz="0 0 1" />
  </joint>
  <link
    name="arm_top_actuator_shaft">
    <inertial>
      <origin
        xyz="1.26496016439326E-08 0.141281564051618 1.00420822213287E-08"
        rpy="0 0 0" />
      <mass
        value="0.707194769757707" />
      <inertia
        ixx="0.00473421939242267"
        ixy="1.09028476447245E-11"
        ixz="-3.86660305010979E-11"
        iyy="3.53245823063994E-05"
        iyz="7.71321415988945E-10"
        izz="0.00473445881104602" />
    </inertial>
    <visual>
      <origin
        xyz="0 0 0"
        rpy="0 0 0" />
      <geometry>
        <mesh
          filename="package://owr_bluetounge2_tf/meshes/arm_top_actuator_shaft.STL" />
      </geometry>
      <material
        name="">
        <color
          rgba="0.647058823529412 0.619607843137255 0.588235294117647 1" />
      </material>
    </visual>
    <collision>
      <origin
        xyz="0 0 0"
        rpy="0 0 0" />
      <geometry>
        <mesh
          filename="package://owr_bluetounge2_tf/meshes/arm_top_actuator_shaft.STL" />
      </geometry>
    </collision>
  </link>
  <joint
    name="arm_top_actuator"
    type="prismatic">
    <origin
      xyz="-0.0176725925011517 0.0587053523428329 0.0339996000000025"
      rpy="-8.6389229103645E-16 -1.1518563880486E-15 0.292409670050612" />
    <parent
      link="arm_top_actuator_base" />
    <child
      link="arm_top_actuator_shaft" />
    <axis
      xyz="-0.0879079473151551 0.996128602540272 0" />
     <limit
      lower="0"
      upper="0.3"
      effort="0"
      velocity="0" />
  </joint>
  <link
    name="arm_top_plates">
    <inertial>
      <origin
        xyz="0.309460599938482 0.0699553674781654 -0.0419999999999997"
        rpy="0 0 0" />
      <mass
        value="0.632836443083174" />
      <inertia
        ixx="0.00302215800706787"
        ixy="0.00205816304102921"
        ixz="-8.26704156520197E-18"
        iyy="0.016197416916534"
        iyz="-1.84314369322536E-18"
        izz="0.0168233830233193" />
    </inertial>
    <visual>
      <origin
        xyz="0 0 0"
        rpy="0 0 0" />
      <geometry>
        <mesh
          filename="package://owr_bluetounge2_tf/meshes/arm_top_plates.STL" />
      </geometry>
      <material
        name="">
        <color
          rgba="0.898039215686275 0.92156862745098 0.929411764705882 1" />
      </material>
    </visual>
    <collision>
      <origin
        xyz="0 0 0"
        rpy="0 0 0" />
      <geometry>
        <mesh
          filename="package://owr_bluetounge2_tf/meshes/arm_top_plates.STL" />
      </geometry>
    </collision>
  </link>
  <joint
    name="arm_top_actuator_top_rotate"
    type="fixed">
    <origin
      xyz="-0.100495123315673 -0.178948287934891 -0.0419995999999991"
      rpy="-3.14159265358979 -5.48172618408671E-16 1.70371717647395" />
    <parent
      link="arm_top_actuator_shaft" />
    <child
      link="arm_top_plates" />
    <axis
      xyz="0 0 -1" />
  </joint>
  <link
    name="arm_top_plate_base_link">
    <inertial>
      <origin
        xyz="-0.0319999997488061 -6.03117764064187E-11 2.49496479032274E-10"
        rpy="0 0 0" />
      <mass
        value="0.00799266011357944" />
      <inertia
        ixx="3.9796353213501E-08"
        ixy="-3.95506070134573E-20"
        ixz="1.1687317592823E-19"
        iyy="1.29764552806623E-05"
        iyz="2.84550130718242E-22"
        izz="1.29764552806623E-05" />
    </inertial>
    <visual>
      <origin
        xyz="0 0 0"
        rpy="0 0 0" />
      <geometry>
        <mesh
          filename="package://owr_bluetounge2_tf/meshes/arm_top_plate_base_link.STL" />
      </geometry>
      <material
        name="">
        <color
          rgba="0.647058823529412 0.619607843137255 0.588235294117647 1" />
      </material>
    </visual>
    <collision>
      <origin
        xyz="0 0 0"
        rpy="0 0 0" />
      <geometry>
        <mesh
          filename="package://owr_bluetounge2_tf/meshes/arm_top_plate_base_link.STL" />
      </geometry>
    </collision>
  </link>
  <joint
    name="arm_top_plate_base_link"
    type="fixed">
    <origin
      xyz="0 0 -0.0100000002511936"
      rpy="1.7589422877175 -1.5707963267949 0" />
    <parent
      link="arm_top_plates" />
    <child
      link="arm_top_plate_base_link" />
    <axis
      xyz="-1 0 0" />
  </joint>
  <link
    name="arm_bottom_plates">
    <inertial>
      <origin
        xyz="0.213559152071814 0.0328810534532391 -0.025999999999998"
        rpy="0 0 0" />
      <mass
        value="0.523833534252721" />
      <inertia
        ixx="0.000841855598383575"
        ixy="-0.00144200507522861"
        ixz="-1.30578599148723E-17"
        iyy="0.0172834629369885"
        iyz="-1.40946282423116E-18"
        izz="0.0173128299283051" />
    </inertial>
    <visual>
      <origin
        xyz="0 0 0"
        rpy="0 0 0" />
      <geometry>
        <mesh
          filename="package://owr_bluetounge2_tf/meshes/arm_bottom_plates.STL" />
      </geometry>
      <material
        name="">
        <color
          rgba="0.898039215686275 0.92156862745098 0.929411764705882 1" />
      </material>
    </visual>
    <collision>
      <origin
        xyz="0 0 0"
        rpy="0 0 0" />
      <geometry>
        <mesh
          filename="package://owr_bluetounge2_tf/meshes/arm_bottom_plates.STL" />
      </geometry>
    </collision>
  </link>
  <joint
    name="arm_bottom_plates_rotate"
    type="fixed">
    <origin
      xyz="0.0275184794744797 -0.0259999999999933 0.153127996289484"
      rpy="1.57079632679489 -1.14066443094574 1.37649429779348E-13" />
    <parent
      link="arm_base" />
    <child
      link="arm_bottom_plates" />
    <axis
      xyz="0 0 1" />
  </joint>
  <link
    name="arm_bottom_actuator_base">
    <inertial>
      <origin
        xyz="0.0320003841319003 0.104575352005021 -0.0702153368949235"
        rpy="0 0 0" />
      <mass
        value="0.5292185810438" />
      <inertia
        ixx="0.00602555553133332"
        ixy="5.68332302083148E-10"
        ixz="-5.27631557938274E-10"
        iyy="0.00124306331821803"
        iyz="-0.00209951381081089"
        izz="0.00490031574372386" />
    </inertial>
    <visual>
      <origin
        xyz="0 0 0"
        rpy="0 0 0" />
      <geometry>
        <mesh
          filename="package://owr_bluetounge2_tf/meshes/arm_bottom_actuator_base.STL" />
      </geometry>
      <material
        name="">
        <color
          rgba="0.647058823529412 0.619607843137255 0.588235294117647 1" />
      </material>
    </visual>
    <collision>
      <origin
        xyz="0 0 0"
        rpy="0 0 0" />
      <geometry>
        <mesh
          filename="package://owr_bluetounge2_tf/meshes/arm_bottom_actuator_base.STL" />
      </geometry>
    </collision>
  </link>
  <joint
    name="arm_bottom_actuator_base_rotate"
    type="fixed">
    <origin
      xyz="0 0.0879999874476814 -0.0579999944206897"
      rpy="0.00603226555870947 -1.57079631189374 -1.14785595903188" />
    <parent
      link="arm_bottom_plates" />
    <child
      link="arm_bottom_actuator_base" />
    <axis
      xyz="-1 0 0" />
  </joint>
  <link
    name="arm_bottom_actuator_shaft">
    <inertial>
      <origin
        xyz="1.69515020076449E-08 0.166668235423207 1.20563901639947E-08"
        rpy="0 0 0" />
      <mass
        value="0.834414953724231" />
      <inertia
        ixx="0.00776037768009465"
        ixy="-6.95961074830847E-11"
        ixz="-4.04210037294704E-11"
        iyy="4.16629664849022E-05"
        iyz="1.0026361455479E-09"
        izz="0.00776061710222152" />
    </inertial>
    <visual>
      <origin
        xyz="0 0 0"
        rpy="0 0 0" />
      <geometry>
        <mesh
          filename="package://owr_bluetounge2_tf/meshes/arm_bottom_actuator_shaft.STL" />
      </geometry>
      <material
        name="">
        <color
          rgba="0.647058823529412 0.619607843137255 0.588235294117647 1" />
      </material>
    </visual>
    <collision>
      <origin
        xyz="0 0 0"
        rpy="0 0 0" />
      <geometry>
        <mesh
          filename="package://owr_bluetounge2_tf/meshes/arm_bottom_actuator_shaft.STL" />
      </geometry>
    </collision>
  </link>
  <joint
    name="arm_bottom_actuator"
    type="prismatic">
    <origin
      xyz="0.0320003944226702 0.0808917432002021 -0.0448335334962513"
      rpy="-1.57079632679491 -1.06470265084296 1.57079632679491" />
    <parent
      link="arm_bottom_actuator_base" />
    <child
      link="arm_bottom_actuator_shaft" />
    <axis
      xyz="-0.0880363362662565 0.996117263928708 0" />
     <limit
      lower="0"
      upper="0.3"
      effort="0"
      velocity="0" />
  </joint>
  <link
    name="arm_lower_bottom_plates">
    <inertial>
      <origin
        xyz="-0.116987046396621 -0.0117851282028598 0.0219999953477101"
        rpy="0 0 0" />
      <mass
        value="0.421175783744303" />
      <inertia
        ixx="0.00035159670734907"
        ixy="-0.000555743088062233"
        ixz="-1.25027222970043E-11"
        iyy="0.00986604490533431"
        iyz="-5.06834412763654E-12"
        izz="0.00988021585128046" />
    </inertial>
    <visual>
      <origin
        xyz="0 0 0"
        rpy="0 0 0" />
      <geometry>
        <mesh
          filename="package://owr_bluetounge2_tf/meshes/arm_lower_bottom_plates.STL" />
      </geometry>
      <material
        name="">
        <color
          rgba="0.898039215686275 0.92156862745098 0.929411764705882 1" />
      </material>
    </visual>
    <collision>
      <origin
        xyz="0 0 0"
        rpy="0 0 0" />
      <geometry>
        <mesh
          filename="package://owr_bluetounge2_tf/meshes/arm_lower_bottom_plates.STL" />
      </geometry>
    </collision>
  </link>
  <joint
    name="arm_lower_bottom_plates_rotate"
    type="fixed">
    <origin
      xyz="-0.0472198179654527 0.446676991521919 -0.0219995999980216"
      rpy="1.2490009027033E-16 -8.32667268468867E-17 -0.834690804163616" />
    <parent
      link="arm_bottom_actuator_shaft" />
    <child
      link="arm_lower_bottom_plates" />
    <axis
      xyz="0 0 1" />
  </joint>
  <link
    name="arm_sync_plate_lower">
    <inertial>
      <origin
        xyz="0.0400000000000004 1.85748495473703E-08 4.04874333503891E-08"
        rpy="0 0 0" />
      <mass
        value="0.0201536396119193" />
      <inertia
        ixx="1.01091490191227E-07"
        ixy="1.59538321864423E-21"
        ixz="7.18240925879794E-21"
        iyy="1.07580809356551E-05"
        iyz="1.65509604595778E-35"
        izz="1.07580809356551E-05" />
    </inertial>
    <visual>
      <origin
        xyz="0 0 0"
        rpy="0 0 0" />
      <geometry>
        <mesh
          filename="package://owr_bluetounge2_tf/meshes/arm_sync_plate_lower.STL" />
      </geometry>
      <material
        name="">
        <color
          rgba="0.647058823529412 0.619607843137255 0.588235294117647 1" />
      </material>
    </visual>
    <collision>
      <origin
        xyz="0 0 0"
        rpy="0 0 0" />
      <geometry>
        <mesh
          filename="package://owr_bluetounge2_tf/meshes/arm_sync_plate_lower.STL" />
      </geometry>
    </collision>
  </link>
  <joint
    name="arm_sync_plate_lower"
    type="fixed">
    <origin
      xyz="0 0 0.0619999999999988"
      rpy="0.328597128236783 1.5707963267949 0" />
    <parent
      link="arm_lower_bottom_plates" />
    <child
      link="arm_sync_plate_lower" />
    <axis
      xyz="-1 0 0" />
  </joint>
  <link
    name="claw_base">
    <inertial>
      <origin
        xyz="-0.0277171001001676 0.0175578017668822 -0.0146145490965356"
        rpy="0 0 0" />
      <mass
        value="0.0771754639307836" />
      <inertia
        ixx="5.79421746872489E-05"
        ixy="1.42709587988055E-05"
        ixz="2.17406635895082E-06"
        iyy="8.3574717699544E-05"
        iyz="9.6225953294956E-06"
        izz="0.000112583876704831" />
    </inertial>
    <visual>
      <origin
        xyz="0 0 0"
        rpy="0 0 0" />
      <geometry>
        <mesh
          filename="package://owr_bluetounge2_tf/meshes/claw_base.STL" />
      </geometry>
      <material
        name="">
        <color
          rgba="0.647058823529412 0.619607843137255 0.588235294117647 1" />
      </material>
    </visual>
    <collision>
      <origin
        xyz="0 0 0"
        rpy="0 0 0" />
      <geometry>
        <mesh
          filename="package://owr_bluetounge2_tf/meshes/claw_base.STL" />
      </geometry>
    </collision>
  </link>
  <joint
    name="claw_base"
    type="fixed">
    <origin
      xyz="-0.437627718488799 -0.0353239921224943 0.021999999999998"
      rpy="1.5707963267949 -6.93889390390723E-17 -2.31503249752949" />
    <parent
      link="arm_lower_bottom_plates" />
    <child
      link="claw_base" />
    <axis
      xyz="0 -1 0" />
  </joint>
  <link
    name="claw_wrist">
    <inertial>
      <origin
        xyz="0.000838226385520766 0.106171608821904 -0.000503683338309968"
        rpy="0 0 0" />
      <mass
        value="0.0918795943669829" />
      <inertia
        ixx="0.000210708869369774"
        ixy="-2.62471832830936E-06"
        ixz="1.66502369226247E-05"
        iyy="5.23027603755915E-05"
        iyz="-3.00026762809218E-06"
        izz="0.000182589552187672" />
    </inertial>
    <visual>
      <origin
        xyz="0 0 0"
        rpy="0 0 0" />
      <geometry>
        <mesh
          filename="package://owr_bluetounge2_tf/meshes/claw_wrist.STL" />
      </geometry>
      <material
        name="">
        <color
          rgba="0.898039215686275 0.92156862745098 0.929411764705882 1" />
      </material>
    </visual>
    <collision>
      <origin
        xyz="0 0 0"
        rpy="0 0 0" />
      <geometry>
        <mesh
          filename="package://owr_bluetounge2_tf/meshes/claw_wrist.STL" />
      </geometry>
    </collision>
  </link>
  <joint
    name="claw_wrist_joint"
    type="fixed">
    <origin
      xyz="-0.055634994248799 0 -0.0468700188956506"
      rpy="-4.03760624151054E-07 0.0889875109761181 -1.57079636267715" />
    <parent
      link="claw_base" />
    <child
      link="claw_wrist" />
    <axis
      xyz="0 0.999999999998984 0" />
  </joint>
  <link
    name="claw_right">
    <inertial>
      <origin
        xyz="-0.0219697875013496 0.00199994968369344 -0.0295222751643468"
        rpy="0 0 0" />
      <mass
        value="0.019697229996406" />
      <inertia
        ixx="7.16643741208075E-06"
        ixy="-3.30425192890112E-13"
        ixz="-1.61956966154489E-06"
        iyy="1.04568129091312E-05"
        iyz="1.45138326003768E-12"
        izz="3.34290144370813E-06" />
    </inertial>
    <visual>
      <origin
        xyz="0 0 0"
        rpy="0 0 0" />
      <geometry>
        <mesh
          filename="package://owr_bluetounge2_tf/meshes/claw_right.STL" />
      </geometry>
      <material
        name="">
        <color
          rgba="0.898039215686275 0.92156862745098 0.929411764705882 1" />
      </material>
    </visual>
    <collision>
      <origin
        xyz="0 0 0"
        rpy="0 0 0" />
      <geometry>
        <mesh
          filename="package://owr_bluetounge2_tf/meshes/claw_right.STL" />
      </geometry>
    </collision>
  </link>
  <joint
    name="claw_right_close"
    type="fixed">
    <origin
      xyz="0.00593469734999167 0.170021528713698 0.017524087928418"
      rpy="-1.57079631288864 1.13618506217272 -3.14159264149837" />
    <parent
      link="claw_wrist" />
    <child
      link="claw_right" />
    <axis
      xyz="0 -0.999999999999744 0" />
  </joint>
  <link
    name="claw_left">
    <inertial>
      <origin
        xyz="-0.0219696013554269 0.002000052887282 -0.0295227352466975"
        rpy="0 0 0" />
      <mass
        value="0.0196972369456186" />
      <inertia
        ixx="7.16697518798111E-06"
        ixy="3.46899682805753E-13"
        ixz="-1.6197471448033E-06"
        iyy="1.04573560728628E-05"
        iyz="-1.52369422329915E-12"
        izz="3.34290685007069E-06" />
    </inertial>
    <visual>
      <origin
        xyz="0 0 0"
        rpy="0 0 0" />
      <geometry>
        <mesh
          filename="package://owr_bluetounge2_tf/meshes/claw_left.STL" />
      </geometry>
      <material
        name="">
        <color
          rgba="0.898039215686275 0.92156862745098 0.929411764705882 1" />
      </material>
    </visual>
    <collision>
      <origin
        xyz="0 0 0"
        rpy="0 0 0" />
      <geometry>
        <mesh
          filename="package://owr_bluetounge2_tf/meshes/claw_left.STL" />
      </geometry>
    </collision>
  </link>
  <joint
    name="claw_left_close"
    type="fixed">
    <origin
      xyz="-0.005930501944748 0.170021528163737 -0.0175355586756956"
      rpy="1.57079626487633 -1.13618506217272 5.38360649714105E-08" />
    <parent
      link="claw_wrist" />
    <child
      link="claw_left" />
    <axis
      xyz="0 0.999999999999737 0" />
  </joint>
  <link
    name="claw_upper_link">
    <inertial>
      <origin
        xyz="0.0479999999999978 7.82630262818884E-08 -5.3292095403279E-08"
        rpy="0 0 0" />
      <mass
        value="0.0242072994446992" />
      <inertia
        ixx="1.21523202517134E-07"
        ixy="2.34219121203909E-20"
        ixz="-8.22647662796237E-20"
        iyy="1.85519155970028E-05"
        iyz="-1.00058079141993E-34"
        izz="1.85519155970028E-05" />
    </inertial>
    <visual>
      <origin
        xyz="0 0 0"
        rpy="0 0 0" />
      <geometry>
        <mesh
          filename="package://owr_bluetounge2_tf/meshes/claw_upper_link.STL" />
      </geometry>
      <material
        name="">
        <color
          rgba="0.647058823529412 0.619607843137255 0.588235294117647 1" />
      </material>
    </visual>
    <collision>
      <origin
        xyz="0 0 0"
        rpy="0 0 0" />
      <geometry>
        <mesh
          filename="package://owr_bluetounge2_tf/meshes/claw_upper_link.STL" />
      </geometry>
    </collision>
  </link>
  <joint
    name="claw_upper_link_joint"
    type="fixed">
    <origin
      xyz="-0.00727246239987009 -0.0479999999999962 0.0230239566957189"
      rpy="1.07283329897131 1.70002900645727E-15 1.5707963267949" />
    <parent
      link="claw_base" />
    <child
      link="claw_upper_link" />
    <axis
      xyz="-1 0 0" />
  </joint>
  <link
    name="arm_sync_plates">
    <inertial>
      <origin
        xyz="0.0399999999517592 0.0256980370864562 0.00182881496444195"
        rpy="0 0 0" />
      <mass
        value="0.12928420888469" />
      <inertia
        ixx="0.000206138452596927"
        ixy="7.25079977671362E-19"
        ixz="-6.09863722023096E-20"
        iyy="0.000299757952842738"
        iyz="-6.35188563590686E-06"
        izz="0.000210953020541722" />
    </inertial>
    <visual>
      <origin
        xyz="0 0 0"
        rpy="0 0 0" />
      <geometry>
        <mesh
          filename="package://owr_bluetounge2_tf/meshes/arm_sync_plates.STL" />
      </geometry>
      <material
        name="">
        <color
          rgba="0.647058823529412 0.619607843137255 0.588235294117647 1" />
      </material>
    </visual>
    <collision>
      <origin
        xyz="0 0 0"
        rpy="0 0 0" />
      <geometry>
        <mesh
          filename="package://owr_bluetounge2_tf/meshes/arm_sync_plates.STL" />
      </geometry>
    </collision>
  </link>
  <joint
    name="arm_sync_plates_rotate"
    type="fixed">
    <origin
      xyz="0.534024004425634 0 -0.0659999999517558"
      rpy="0.0248080188130133 -1.57079631189374 -1.16632295052724" />
    <parent
      link="arm_bottom_plates" />
    <child
      link="arm_sync_plates" />
    <axis
      xyz="-1 0 0" />
  </joint>
  <link
    name="arm_lower_top_plates">
    <inertial>
      <origin
        xyz="0.0480000005095059 0.0379639515356004 0.168599314143766"
        rpy="0 0 0" />
      <mass
        value="0.222440263368329" />
      <inertia
        ixx="0.00384135136405407"
        ixy="-4.44522890719057E-18"
        ixz="-2.49840838122128E-17"
        iyy="0.00404127512700447"
        iyz="0.000815046885472545"
        izz="0.000605145202590495" />
    </inertial>
    <visual>
      <origin
        xyz="0 0 0"
        rpy="0 0 0" />
      <geometry>
        <mesh
          filename="package://owr_bluetounge2_tf/meshes/arm_lower_top_plates.STL" />
      </geometry>
      <material
        name="">
        <color
          rgba="0.647058823529412 0.619607843137255 0.588235294117647 1" />
      </material>
    </visual>
    <collision>
      <origin
        xyz="0 0 0"
        rpy="0 0 0" />
      <geometry>
        <mesh
          filename="package://owr_bluetounge2_tf/meshes/arm_lower_top_plates.STL" />
      </geometry>
    </collision>
  </link>
  <joint
    name="arm_lower_top_plates_rotate"
    type="fixed">
    <origin
      xyz="0.088000000461267 0.0462969388039673 -0.0518444185888435"
      rpy="3.14159265358973 1.37390099297363E-15 -3.14159265358979" />
    <parent
      link="arm_sync_plates" />
    <child
      link="arm_lower_top_plates" />
    <axis
      xyz="-1 0 0" />
  </joint>
  <!-- Gazebo stuff beyond this point -->
    <xacro:property name="PI" value="3.14159265359" />
    <gazebo>
        <plugin name="gazebo_ros_control" filename="libgazebo_ros_control.so">
        <robotNamespace>/</robotNamespace>
        </plugin>
    </gazebo>
    <xacro:property name="gearbox_mechReduction" value="10" />
    <transmission name="front_left_wheel_axel">
        <type>transmission_interface/SimpleTransmission</type>
        <joint name="front_left_wheel_axel">
        <hardwareInterface>VelocityJointInterface</hardwareInterface>
        </joint>
        <actuator name="front_left_wheel_motor">
        <mechanicalReduction>${gearbox_mechReduction}</mechanicalReduction>
        <hardwareInterface>VelocityJointInterface</hardwareInterface>
        </actuator>
    </transmission>
    <transmission name="back_left_wheel_axel">
        <type>transmission_interface/SimpleTransmission</type>
        <joint name="back_left_wheel_axel">
                <hardwareInterface>VelocityJointInterface</hardwareInterface>
        </joint>
        <actuator name="back_left_wheel_motor">
        <mechanicalReduction>${gearbox_mechReduction}</mechanicalReduction>
        <hardwareInterface>VelocityJointInterface</hardwareInterface>
        </actuator>
    </transmission>
    <transmission name="front_right_wheel_axel">
        <type>transmission_interface/SimpleTransmission</type>
        <joint name="front_right_wheel_axel">
        <hardwareInterface>VelocityJointInterface</hardwareInterface>
        </joint>
        <actuator name="front_right_wheel_motor">
        <mechanicalReduction>${gearbox_mechReduction}</mechanicalReduction>
        <hardwareInterface>VelocityJointInterface</hardwareInterface>
        </actuator>
    </transmission>
    <transmission name="back_right_wheel_axel">
        <type>transmission_interface/SimpleTransmission</type>
        <joint name="back_right_wheel_axel">
            <hardwareInterface>VelocityJointInterface</hardwareInterface>
        </joint>
        <actuator name="back_right_wheel_motor">
        <mechanicalReduction>${gearbox_mechReduction}</mechanicalReduction>
        <hardwareInterface>VelocityJointInterface</hardwareInterface>
        </actuator>
    </transmission>
    <transmission name="back_right_swerve">
        <type>transmission_interface/SimpleTransmission</type>
        <joint name="back_right_swerve">
            <hardwareInterface>PositionJointInterface</hardwareInterface>
        </joint>
        <actuator name="back_right_swerve_motor">
        <mechanicalReduction>${gearbox_mechReduction}</mechanicalReduction>
        <hardwareInterface>PositionJointInterface</hardwareInterface>
        </actuator>
    </transmission>
    <transmission name="front_right_swerve">
        <type>transmission_interface/SimpleTransmission</type>
        <joint name="front_right_swerve">
            <hardwareInterface>PositionJointInterface</hardwareInterface>
        </joint>
        <actuator name="front_right_swerve_motor">
        <mechanicalReduction>${gearbox_mechReduction}</mechanicalReduction>
        <hardwareInterface>PositionJointInterface</hardwareInterface>
        </actuator>
    </transmission>
    <transmission name="back_left_swerve">
        <type>transmission_interface/SimpleTransmission</type>
        <joint name="back_left_swerve">
            <hardwareInterface>PositionJointInterface</hardwareInterface>
        </joint>
        <actuator name="back_left_swerve_motor">
        <mechanicalReduction>${gearbox_mechReduction}</mechanicalReduction>
        <hardwareInterface>PositionJointInterface</hardwareInterface>
        </actuator>
    </transmission>
    <transmission name="front_left_swerve">
        <type>transmission_interface/SimpleTransmission</type>
        <joint name="front_left_swerve">
            <hardwareInterface>PositionJointInterface</hardwareInterface>
        </joint>
        <actuator name="front_left_swerve_motor">
        <mechanicalReduction>${gearbox_mechReduction}</mechanicalReduction>
        <hardwareInterface>PositionJointInterface</hardwareInterface>
        </actuator>
    </transmission>
    <transmission name="laser_tilt_joint">
        <type>transmission_interface/SimpleTransmission</type>
        <joint name="laser_tilt_joint">
            <hardwareInterface>PositionJointInterface</hardwareInterface>
        </joint>
        <actuator name="laser_tilt_motor">
        <mechanicalReduction>${gearbox_mechReduction}</mechanicalReduction>
        <hardwareInterface>PositionJointInterface</hardwareInterface>
        </actuator>
    </transmission>
    <gazebo reference="laser_frame">
        <sensor type="gpu_ray" name="laser_frame">
        <pose>0 0 0 0 0 0</pose>
        <visualize>false</visualize>
        <update_rate>40</update_rate>
        <ray>
            <scan>
            <horizontal>
                <samples>720</samples>
                <resolution>1</resolution>
                <min_angle>-2.35619</min_angle>
                <max_angle>2.35619</max_angle>
            </horizontal>
            </scan>
            <range>
            <min>0.10</min>
            <max>30.0</max>
            <resolution>0.01</resolution>
            </range>
            <noise>
            <type>gaussian</type>-->
            <!-- Noise parameters based on published spec for Hokuyo laser
                achieving "+-30mm" accuracy at range < 10m.  A mean of 0.0m and
                stddev of 0.01m will put 99.7% of samples within 0.03m of the true
                reading. -->
            <mean>0.0</mean>
            <stddev>0.01</stddev>
            </noise>
        </ray>
        <plugin name="gazebo_ros_head_hokuyo_controller" filename="libgazebo_ros_gpu_laser.so">
            <topicName>/laser/scan</topicName>
            <frameName>laser_frame</frameName>
        </plugin>
        </sensor>
    </gazebo>
</robot>
