<?xml version="1.0"?>
<robot
        xmlns:xacro="http://www.ros.org/wiki/xacro"
        name="owr_numbat_tf">
  <link name="base_link">

  </link>
  <link
    name="rover_model">
    <inertial>
      <origin
        xyz="0.199001521355698 0.401976534326884 0.644578776800536"
        rpy="0 0 0" />
      <mass
        value="33.4975943636999" />
      <inertia
        ixx="0.0125052741751253"
        ixy="0.00142309072234029"
        ixz="0.00557644568946697"
        iyy="0.0456048995470643"
        iyz="0.000645084117129033"
        izz="0.0337193883299707" />
    </inertial>
    <visual>
      <origin
        xyz="0 0 0"
        rpy="0 0 0" />
      <geometry>
        <mesh
          filename="package://owr_numbat_tf/meshes/base_link.STL" />
      </geometry>
      <material
        name="">
        <color
          rgba="0.792156862745098 0.819607843137255 0.933333333333333 1" />
      </material>
    </visual>
    <collision>
      <origin
        xyz="0 0 0"
        rpy="0 0 0" />
      <geometry>
        <mesh
          filename="package://owr_numbat_tf/meshes/base_link.STL" />
      </geometry>
    </collision>
  </link>
  <joint
          name="base_link_rover"
          type="fixed">
    <origin
            xyz="0.2 -0.65 0"
            rpy="0 0 3.14159265359" />
    <parent
            link="base_link" />
    <child
            link="rover_model" />
    <axis
            xyz="0 0 0" />
  </joint>
  <link
          name="laser_tilt">
    <inertial>
      <origin
              xyz="-0.0326669331300311 0.000449239090195036 0.0154731252391825"
              rpy="0 0 0" />
      <mass
              value="0.0609125923338383" />
      <inertia
              ixx="2.00361198600938E-05"
              ixy="-5.20398520467511E-07"
              ixz="1.67772001955164E-06"
              iyy="5.68087099458121E-05"
              iyz="-4.03110668527991E-08"
              izz="5.87542018274252E-05" />
    </inertial>
    <visual>
      <origin
              xyz="0 0 0"
              rpy="0 0 0" />
      <geometry>
        <mesh
                filename="package://owr_numbat_tf/meshes/laser_tilt.STL" />
      </geometry>
      <material
              name="">
        <color
                rgba="0.792156862745098 0.819607843137255 0.933333333333333 1" />
      </material>
    </visual>
    <collision>
      <origin
              xyz="0 0 0"
              rpy="0 0 0" />
      <geometry>
        <mesh
                filename="package://owr_numbat_tf/meshes/laser_tilt.STL" />
      </geometry>
    </collision>
  </link>
  <joint
          name="laser_tilt_base"
          type="fixed">
    <origin
            xyz="-0.1 -0.75 0.47"
            rpy="-4.0766001685455E-16 2.71143453751384E-15 -3.14214183115679" />
    <parent
            link="rover_model" />
    <child
            link="laser_tilt" />
    <axis
            xyz="0 0 0" />
  </joint>
  <link
          name="laser_tilt_tilt">
    <inertial>
      <origin
              xyz="-0.0207354942246256 -0.0110062171521322 0.0363962516011186"
              rpy="0 0 0" />
      <mass
              value="0.063245803268312" />
      <inertia
              ixx="3.67872840111064E-05"
              ixy="2.45249846765993E-06"
              ixz="1.33088294535402E-06"
              iyy="4.06730444934804E-05"
              iyz="6.96179679390717E-07"
              izz="4.48239101958926E-05" />
    </inertial>
    <visual>
      <origin
              xyz="0 0 0"
              rpy="0 0 0" />
      <geometry>
        <mesh
                filename="package://owr_numbat_tf/meshes/laser_tilt_tilt.STL" />
      </geometry>
      <material
              name="">
        <color
                rgba="0.792156862745098 0.819607843137255 0.933333333333333 1" />
      </material>
    </visual>
    <collision>
      <origin
              xyz="0 0 0"
              rpy="0 0 0" />
      <geometry>
        <mesh
                filename="package://owr_numbat_tf/meshes/laser_tilt_tilt.STL" />
      </geometry>
    </collision>
  </link>
  <joint
          name="laser_tilt_joint"
          type="revolute">
    <origin
            xyz="-0.00692854336717914 -0.01905 0.029"
            rpy="-1.5707963267949 1.08521967863993 0" />
    <parent
            link="laser_tilt" />
    <child
            link="laser_tilt_tilt" />
    <axis
            xyz="0 0 1" />
    <limit
            lower="-0.785398"
            upper="1.5708"
            effort="0"
            velocity="0" />
  </joint>
  <link
          name="lidar_frame">
    <inertial>
      <origin
              xyz="-0.000639925729432167 0.000662656077548368 -0.0176677612707939"
              rpy="0 0 0" />
      <mass
              value="0.229160254803044" />
      <inertia
              ixx="0.000208997482925673"
              ixy="4.81938834051271E-07"
              ixz="1.1237905876103E-06"
              iyy="0.000213298877696199"
              iyz="1.24374624615713E-07"
              izz="0.000112442329412222" />
    </inertial>
    <visual>
      <origin
              xyz="0 0 0"
              rpy="0 0 0" />
      <geometry>
        <mesh
                filename="package://owr_numbat_tf/meshes/lidar_frame.STL" />
      </geometry>
      <material
              name="">
        <color
                rgba="0 0 0 1" />
      </material>
    </visual>
    <collision>
      <origin
              xyz="0 0 0"
              rpy="0 0 0" />
      <geometry>
        <mesh
                filename="package://owr_numbat_tf/meshes/lidar_frame.STL" />
      </geometry>
    </collision>
  </link>
  <joint
          name="lidar_frame_base"
          type="fixed">
    <origin
            xyz="-0.0922144508966998 -0.0394134633802184 0.0346559749585283"
            rpy="1.5707963267949 0.110221873047514 -1.08521967863993" />
    <parent
            link="laser_tilt_tilt" />
    <child
            link="lidar_frame" />
    <axis
            xyz="0 0 0" />
  </joint>
  <link
    name="back_right_wheel_axel">
    <inertial>
      <origin
        xyz="-0.0517688079644882 0.0887190484893181 2.22044604925031E-16"
        rpy="0 0 0" />
      <mass
        value="0.674113164049984" />
      <inertia
        ixx="0"
        ixy="0"
        ixz="0"
        iyy="0"
        iyz="0"
        izz="0" />
    </inertial>
    <visual>
      <origin
        xyz="0 0 0"
        rpy="0 0 0" />
      <geometry>
        <mesh
          filename="package://owr_numbat_tf/meshes/Front Left Axle.STL" />
      </geometry>
      <material
        name="">
        <color
          rgba="0.792156862745098 0.819607843137255 0.933333333333333 1" />
      </material>
    </visual>
    <collision>
      <origin
        xyz="0 0 0"
        rpy="0 0 0" />
      <geometry>
        <mesh
          filename="package://owr_numbat_tf/meshes/Front Left Axle.STL" />
      </geometry>
    </collision>
  </link>
  <joint
    name="back_right_swerve"
    type="continuous">
    <origin
      xyz="0.62684 -0.40335 0.13495"
      rpy="1.5708 6.088E-17 1.6778" />
    <parent
      link="rover_model" />
    <child
      link="back_right_wheel_axel" />
    <axis
      xyz="0 1 0" />
  </joint>
  <link
    name="back_right wheel">
    <inertial>
      <origin
        xyz="6.06240746492404E-09 -2.77011136112781E-07 -0.00589838982095087"
        rpy="0 0 0" />
      <mass
        value="1.5442893046468" />
      <inertia
        ixx="0"
        ixy="0"
        ixz="0"
        iyy="0"
        iyz="0"
        izz="0" />
    </inertial>
    <visual>
      <origin
        xyz="0 0 0"
        rpy="0 0 0" />
      <geometry>
        <mesh
          filename="package://owr_numbat_tf/meshes/Front Left wheel.STL" />
      </geometry>
      <material
        name="">
        <color
          rgba="0.792156862745098 0.819607843137255 0.933333333333333 1" />
      </material>
    </visual>
    <collision>
      <origin
        xyz="0 0 0"
        rpy="0 0 0" />
      <geometry>
        <mesh
          filename="package://owr_numbat_tf/meshes/Front Left wheel.STL" />
      </geometry>
    </collision>
  </link>
  <joint
    name="back_left_wheel_axel"
    type="continuous">
    <origin
      xyz="0 0.03 0"
      rpy="-1.5708 -0.91526 1.5708" />
    <parent
      link="back_right_wheel_axel" />
    <child
      link="back_right wheel" />
    <axis
      xyz="0 0 1" />
  </joint>
  <link
    name="front_right_wheel_axel">
    <inertial>
      <origin
        xyz="-0.0517688079644883 0.0887190484893179 -4.16333634234434E-17"
        rpy="0 0 0" />
      <mass
        value="0.674113164049983" />
      <inertia
        ixx="0"
        ixy="0"
        ixz="0"
        iyy="0"
        iyz="0"
        izz="0" />
    </inertial>
    <visual>
      <origin
        xyz="0 0 0"
        rpy="0 0 0" />
      <geometry>
        <mesh
          filename="package://owr_numbat_tf/meshes/Back Left Axle.STL" />
      </geometry>
      <material
        name="">
        <color
          rgba="0.792156862745098 0.819607843137255 0.933333333333333 1" />
      </material>
    </visual>
    <collision>
      <origin
        xyz="0 0 0"
        rpy="0 0 0" />
      <geometry>
        <mesh
          filename="package://owr_numbat_tf/meshes/Back Left Axle.STL" />
      </geometry>
    </collision>
  </link>
  <joint
    name="front_right_swerve"
    type="continuous">
    <origin
      xyz="-0.13031 -0.40335 0.13495"
      rpy="1.5708 6.0901E-17 1.4671" />
    <parent
      link="rover_model" />
    <child
      link="front_right_wheel_axel" />
    <axis
      xyz="0 1 0" />
  </joint>
  <link
    name="front_right Wheel">
    <inertial>
      <origin
        xyz="6.06240754819076E-09 -2.77011136001759E-07 -0.00589838982095175"
        rpy="0 0 0" />
      <mass
        value="1.5442893046468" />
      <inertia
        ixx="0"
        ixy="0"
        ixz="0"
        iyy="0"
        iyz="0"
        izz="0" />
    </inertial>
    <visual>
      <origin
        xyz="0 0 0"
        rpy="0 0 0" />
      <geometry>
        <mesh
          filename="package://owr_numbat_tf/meshes/Back Left Wheel.STL" />
      </geometry>
      <material
        name="">
        <color
          rgba="0.792156862745098 0.819607843137255 0.933333333333333 1" />
      </material>
    </visual>
    <collision>
      <origin
        xyz="0 0 0"
        rpy="0 0 0" />
      <geometry>
        <mesh
          filename="package://owr_numbat_tf/meshes/Back Left Wheel.STL" />
      </geometry>
    </collision>
  </link>
  <joint
    name="front_right_wheel_axel"
    type="continuous">
    <origin
      xyz="0 0.0300000000000001 0"
      rpy="1.57079632679489 0.214040970418392 -1.5707963267949" />
    <parent
      link="front_right_wheel_axel" />
    <child
      link="front_right Wheel" />
    <axis
      xyz="0 0 1" />
  </joint>
  <link
    name="front_left_wheel_axel">
    <inertial>
      <origin
        xyz="-0.0517688079644882 0.088719048489318 -5.55111512312578E-17"
        rpy="0 0 0" />
      <mass
        value="0.674113164049983" />
      <inertia
        ixx="0"
        ixy="0"
        ixz="0"
        iyy="0"
        iyz="0"
        izz="0" />
    </inertial>
    <visual>
      <origin
        xyz="0 0 0"
        rpy="0 0 0" />
      <geometry>
        <mesh
          filename="package://owr_numbat_tf/meshes/Back Right Axle.STL" />
      </geometry>
      <material
        name="">
        <color
          rgba="0.792156862745098 0.819607843137255 0.933333333333333 1" />
      </material>
    </visual>
    <collision>
      <origin
        xyz="0 0 0"
        rpy="0 0 0" />
      <geometry>
        <mesh
          filename="package://owr_numbat_tf/meshes/Back Right Axle.STL" />
      </geometry>
    </collision>
  </link>
  <joint
    name="front_left_swerve"
    type="continuous">
    <origin
      xyz="-0.13031 -0.88449 0.13495"
      rpy="1.5708 5.9043E-17 1.3027" />
    <parent
      link="rover_model" />
    <child
      link="front_left_wheel_axel" />
    <axis
      xyz="0 1 0" />
  </joint>
  <link
    name="front_left Wheel">
    <inertial>
      <origin
        xyz="6.06240740941288E-09 -2.77011135974004E-07 -0.00589838982095114"
        rpy="0 0 0" />
      <mass
        value="1.54428930464679" />
      <inertia
        ixx="0"
        ixy="0"
        ixz="0"
        iyy="0"
        iyz="0"
        izz="0" />
    </inertial>
    <visual>
      <origin
        xyz="0 0 0"
        rpy="0 0 0" />
      <geometry>
        <mesh
          filename="package://owr_numbat_tf/meshes/Back Right Wheel.STL" />
      </geometry>
      <material
        name="">
        <color
          rgba="0.792156862745098 0.819607843137255 0.933333333333333 1" />
      </material>
    </visual>
    <collision>
      <origin
        xyz="0 0 0"
        rpy="0 0 0" />
      <geometry>
        <mesh
          filename="package://owr_numbat_tf/meshes/Back Right Wheel.STL" />
      </geometry>
    </collision>
  </link>
  <joint
    name="back_right_wheel_axel"
    type="continuous">
    <origin
      xyz="0 0.0299999999999999 0"
      rpy="-1.57079632679491 -1.13219561486008 1.57079632679491" />
    <parent
      link="front_left_wheel_axel" />
    <child
      link="front_left Wheel" />
    <axis
      xyz="0 0 1" />
  </joint>
  <link
    name="back_left_wheel_axel">
    <inertial>
      <origin
        xyz="-0.0517688079644884 0.088719048489318 -2.22044604925031E-16"
        rpy="0 0 0" />
      <mass
        value="0.674113164049983" />
      <inertia
        ixx="0"
        ixy="0"
        ixz="0"
        iyy="0"
        iyz="0"
        izz="0" />
    </inertial>
    <visual>
      <origin
        xyz="0 0 0"
        rpy="0 0 0" />
      <geometry>
        <mesh
          filename="package://owr_numbat_tf/meshes/Front Right Axle.STL" />
      </geometry>
      <material
        name="">
        <color
          rgba="0.792156862745098 0.819607843137255 0.933333333333333 1" />
      </material>
    </visual>
    <collision>
      <origin
        xyz="0 0 0"
        rpy="0 0 0" />
      <geometry>
        <mesh
          filename="package://owr_numbat_tf/meshes/Front Right Axle.STL" />
      </geometry>
    </collision>
  </link>
  <joint
    name="back_left_swerve"
    type="continuous">
    <origin
      xyz="0.626839262679528 -0.884494656994069 0.13494946923044"
      rpy="1.5707963267949 6.12114355045412E-17 1.54596104769157" />
    <parent
      link="rover_model" />
    <child
      link="back_left_wheel_axel" />
    <axis
      xyz="0 1 0" />
  </joint>
  <link
    name="front_right_Wheel" >
    <inertial>
      <origin
        xyz="6.10794798072689E-09 -2.76999337467387E-07 -0.00589838982429747"
        rpy="0 0 0" />
      <mass
        value="1.54428930379881" />
      <inertia
        ixx="0"
        ixy="0"
        ixz="0"
        iyy="0"
        iyz="0"
        izz="0" />
    </inertial>
    <visual>
      <origin
        xyz="0 0 0"
        rpy="0 0 0" />
      <geometry>
        <mesh
          filename="package://owr_numbat_tf/meshes/Front RIght Wheel.STL" />
      </geometry>
      <material
        name="">
        <color
          rgba="0.792156862745098 0.819607843137255 0.933333333333333 1" />
      </material>
    </visual>
    <collision>
      <origin
        xyz="0 0 0"
        rpy="0 0 0" />
      <geometry>
        <mesh
          filename="package://owr_numbat_tf/meshes/Front RIght Wheel.STL" />
      </geometry>
    </collision>
  </link>
  <joint
    name="front_left_wheel_axel"
    type="continuous">
    <origin
      xyz="0 0.0299999999999999 0"
      rpy="-1.5707963267949 -0.00858284690216311 1.57079632679489" />
    <parent
      link="back_left_wheel_axel" />
    <child
      link="front_right_Wheel" />
    <axis
      xyz="0 0 1" />
  </joint>
    <gazebo>
        <plugin name="gazebo_ros_control" filename="libgazebo_ros_control.so">
        <robotNamespace>/</robotNamespace>
        </plugin>
    </gazebo>
    <xacro:property name="gearbox_mechReduction" value="10" />
  <transmission name="laser_tilt_joint">
    <type>transmission_interface/SimpleTransmission</type>
    <joint name="laser_tilt_joint">
      <hardwareInterface>PositionJointInterface</hardwareInterface>
    </joint>
    <actuator name="laser_tilt_motor">
      <mechanicalReduction>${gearbox_mechReduction}</mechanicalReduction>
      <hardwareInterface>PositionJointInterface</hardwareInterface>
    </actuator>
  </transmission>
  <gazebo reference="laser_frame">
    <sensor type="gpu_ray" name="laser_frame">
      <pose>0 0 0 0 0 0</pose>
      <visualize>false</visualize>
      <update_rate>40</update_rate>
      <ray>
        <scan>
          <horizontal>
            <samples>720</samples>
            <resolution>1</resolution>
            <min_angle>-2.35619</min_angle>
            <max_angle>2.35619</max_angle>
          </horizontal>
        </scan>
        <range>
          <min>0.10</min>
          <max>30.0</max>
          <resolution>0.01</resolution>
        </range>
        <noise>
          <type>gaussian</type>-->
          <!-- Noise parameters based on published spec for Hokuyo laser
              achieving "+-30mm" accuracy at range < 10m.  A mean of 0.0m and
              stddev of 0.01m will put 99.7% of samples within 0.03m of the true
              reading. -->
          <mean>0.0</mean>
          <stddev>0.01</stddev>
        </noise>
      </ray>
      <plugin name="gazebo_ros_head_hokuyo_controller" filename="libgazebo_ros_gpu_laser.so">
        <topicName>/laser/scan</topicName>
        <frameName>laser_frame</frameName>
      </plugin>
    </sensor>
  </gazebo>
</robot>
