<robot
  name="lidar_tilt">
  <link
    name="laser_tilt_base">
    <inertial>
      <origin
        xyz="0.43736 -0.0070195 0.04262"
        rpy="0 0 0" />
      <mass
        value="0.060913" />
      <inertia
        ixx="5.6809E-05"
        ixy="-3.1933E-07"
        ixz="-4.1287E-07"
        iyy="4.2988E-05"
        iyz="1.9097E-05"
        izz="3.5802E-05" />
    </inertial>
    <visual>
      <origin
        xyz="0 0 0"
        rpy="0 0 0" />
      <geometry>
        <mesh
          filename="package://lidar_tilt/meshes/laser_tilt_base.STL" />
      </geometry>
      <material
        name="">
        <color
          rgba="0.79216 0.81961 0.93333 1" />
      </material>
    </visual>
    <collision>
      <origin
        xyz="0 0 0"
        rpy="0 0 0" />
      <geometry>
        <mesh
          filename="package://lidar_tilt/meshes/laser_tilt_base.STL" />
      </geometry>
    </collision>
  </link>
  <link
    name="laser_tilt_tilt">
    <inertial>
      <origin
        xyz="0.027266 0.024274 -0.0025636"
        rpy="0 0 0" />
      <mass
        value="0.060855" />
      <inertia
        ixx="4.334E-05"
        ixy="1.9349E-06"
        ixz="-1.9524E-07"
        iyy="3.4772E-05"
        iyz="-2.8452E-07"
        izz="3.9596E-05" />
    </inertial>
    <visual>
      <origin
        xyz="0 0 0"
        rpy="0 0 0" />
      <geometry>
        <mesh
          filename="package://lidar_tilt/meshes/laser_tilt_tilt.STL" />
      </geometry>
      <material
        name="">
        <color
          rgba="0.79216 0.81961 0.93333 1" />
      </material>
    </visual>
    <collision>
      <origin
        xyz="0 0 0"
        rpy="0 0 0" />
      <geometry>
        <mesh
          filename="package://lidar_tilt/meshes/laser_tilt_tilt.STL" />
      </geometry>
    </collision>
  </link>
  <joint
    name="laser_tilt_joint"
    type="continuous">
    <origin
      xyz="0.3929 -0.01446 -0.014263"
      rpy="0.82137 0 0" />
    <parent
      link="laser_tilt_base" />
    <child
      link="laser_tilt_tilt" />
    <axis
      xyz="-1 0 0" />
  </joint>
</robot>