<?xml version="1.0"?>
<robot xmlns:xacro="http://www.ros.org/wiki/xacro"  name="owr_bluetounge_tf">
    <xacro:property name="PI" value="3.14159265359" />
    <gazebo>
        <plugin name="gazebo_ros_control" filename="libgazebo_ros_control.so">
        <robotNamespace>/</robotNamespace>
        </plugin>
    </gazebo>
    <link name="base_link">
    </link>
    <joint
        name="base_link_joint"
        type="fixed">
        <origin
        xyz="0 0 0 "
        rpy="0 0 0" />
        <parent
        link="base_link" />
        <child
        link="robot_base" />
        <axis
        xyz="0 0 0" />
    </joint>
    <link
        name="robot_base">
        <inertial>
        <origin
            xyz="0.00046273478360065 0.0229210396347507 0.0327540444161599"
            rpy="0 0 0" />
        <mass
            value="8.39051518849641" />
        <inertia
            ixx="0.17571890508763"
            ixy="0.00407753315462676"
            ixz="0.00030790478794065"
            iyy="0.26613638931513"
            iyz="0.000486599852613809"
            izz="0.407552215584655" />
        </inertial>
        <visual>
        <origin
            xyz="0 0 0"
            rpy="0 0 0" />
        <geometry>
            <mesh
            filename="package://owr_bluetounge_tf/meshes/base_link.STL" />
        </geometry>
        <material
            name="">
            <color
            rgba="0.898039215686275 0.92156862745098 0.929411764705882 1" />
        </material>
        </visual>
        <collision>
        <origin
            xyz="0 0 0"
            rpy="0 0 0" />
        <geometry>
            <mesh
            filename="package://owr_bluetounge_tf/meshes/base_link.STL" />
        </geometry>
        </collision>
    </link>
    <link
        name="left_bogey">
        <inertial>
        <origin
            xyz="-0.160279212038914 0.263114246966823 -0.187530743463307"
            rpy="0 0 0" />
        <mass
            value="3.86242084681489" />
        <inertia
            ixx="0.359057643171706"
            ixy="0.00900871558955165"
            ixz="-0.0194307460386673"
            iyy="0.286597578085296"
            iyz="-0.123296086137974"
            izz="0.105948292960839" />
        </inertial>
        <visual>
        <origin
            xyz="0 0 0"
            rpy="0 0 0" />
        <geometry>
            <mesh
            filename="package://owr_bluetounge_tf/meshes/left_bogey.STL" />
        </geometry>
        <material
            name="">
            <color
            rgba="0.898039215686275 0.917647058823529 0.929411764705882 1" />
        </material>
        </visual>
        <collision>
        <origin
            xyz="0 0 0"
            rpy="0 0 0" />
        <geometry>
            <mesh
            filename="package://owr_bluetounge_tf/meshes/left_bogey.STL" />
        </geometry>
        </collision>
    </link>
    <joint
        name="left_axel"
        type="fixed">
        <origin
        xyz="0.523257961487556 0.415609911601108 -0.47742273807323"
        rpy="1.5707963267949 6.12303176911189E-17 1.5707963267949" />
        <parent
        link="robot_base" />
        <child
        link="left_bogey" />
        <axis
        xyz="0 0 0" />
    </joint>
    <link
        name="front_left_wheel">
        <inertial>
        <origin
            xyz="5.55111512312578E-17 -2.96170694409903E-05 0.136489605026699"
            rpy="0 0 0" />
        <mass
            value="2.15472811624945" />
        <inertia
            ixx="0.0154723847547672"
            ixy="1.67633895284835E-23"
            ixz="6.74290171076882E-18"
            iyy="0.0154727320555494"
            iyz="-1.01534941592734E-06"
            izz="0.0180021390861626" />
        </inertial>
        <visual>
        <origin
            xyz="0 0 0"
            rpy="0 0 0" />
        <geometry>
            <mesh
            filename="package://owr_bluetounge_tf/meshes/front_left_wheel.STL" />
        </geometry>
        <material
            name="">
            <color
            rgba="0.647058823529412 0.619607843137255 0.588235294117647 1" />
        </material>
        </visual>
        <collision>
        <origin
            xyz="0 0 0"
            rpy="0 0 0" />
        <geometry>
            <mesh
            filename="package://owr_bluetounge_tf/meshes/front_left_wheel.STL" />
        </geometry>
        </collision>
    </link>
    <joint
        name="front_left_wheel_axel"
        type="continuous">
        <origin
        xyz="-0.25399999999999995 0.0290000000000001 -0.0253999999999999"
        rpy="0 1.57079632679 0 " />
        <parent
        link="left_bogey" />
        <child
        link="front_left_wheel" />
        <axis
        xyz="0 0 1" />
    </joint>
    <link
        name="back_left_bogey">
        <inertial>
        <origin
            xyz="0.214107893734074 -0.168692144671464 -0.161433659322479"
            rpy="3.14159265359 0 0" />
        <mass
            value="5.97230241716652" />
        <inertia
            ixx="0.0697411789225175"
            ixy="-0.00908337945439863"
            ixz="-0.00129187352270989"
            iyy="0.373707858515929"
            iyz="0.00110484816669177"
            izz="0.383266801293246" />
        </inertial>
        <visual>
        <origin
            xyz="0 0 0"
            rpy="3.14159265359 0 0" />
        <geometry>
            <mesh
            filename="package://owr_bluetounge_tf/meshes/back_left_bogey.STL" />
        </geometry>
        <material
            name="">
            <color
            rgba="0.866666666666667 0.909803921568627 1 1" />
        </material>
        </visual>
        <collision>
        <origin
            xyz="0 0 0"
            rpy="3.14159265359 0 0" />
        <geometry>
            <mesh
            filename="package://owr_bluetounge_tf/meshes/back_left_bogey.STL" />
        </geometry>
        </collision>
    </link>
    <joint
        name="back_left_bogey_axel"
        type="fixed">
        <origin
        xyz="-0.00962999999999992 0.00549999999999995 -1.00057881716751"
        rpy="0 -1.5707963267949 0" />
        <parent
        link="left_bogey" />
        <child
        link="back_left_bogey" />
        <axis
        xyz="0 0 0" />
    </joint>
    <link
        name="middle_left_wheel">
        <inertial>
        <origin
            xyz="0 -2.96170694409348E-05 0.136489605026699"
            rpy="0 0 0" />
        <mass
            value="2.15472811624945" />
        <inertia
            ixx="0.0154723847547672"
            ixy="-2.56230745467387E-22"
            ixz="3.77451925719516E-18"
            iyy="0.0154727320555494"
            iyz="-1.01534941592837E-06"
            izz="0.0180021390861626" />
        </inertial>
        <visual>
        <origin
            xyz="0 0 0"
            rpy="0 0 0" />
        <geometry>
            <mesh
            filename="package://owr_bluetounge_tf/meshes/back_left_wheel.STL" />
        </geometry>
        <material
            name="">
            <color
            rgba="0.647058823529412 0.619607843137255 0.588235294117647 1" />
        </material>
        </visual>
        <collision>
        <origin
            xyz="0 0 0"
            rpy="0 0 0" />
        <geometry>
            <mesh
            filename="package://owr_bluetounge_tf/meshes/back_left_wheel.STL" />
        </geometry>
        </collision>
    </link>
    <joint
        name="middle_left_wheel_axel"
        type="continuous">
        <origin
        xyz="0.4754000000000002 0.0235 0.26363"
        rpy="3.14159265358979 0 0" />
        <parent
        link="back_left_bogey" />
        <child
        link="middle_left_wheel" />
        <axis
        xyz="0 0 1" />
    </joint>
    <link
        name="back_left_wheel">
        <inertial>
        <origin
            xyz="0 -2.96170694409348E-05 0.136489605026699"
            rpy="0 0 0" />
        <mass
            value="2.15472811624945" />
        <inertia
            ixx="0.0154723847547672"
            ixy="-2.56230745467387E-22"
            ixz="3.77451925719516E-18"
            iyy="0.0154727320555494"
            iyz="-1.01534941592837E-06"
            izz="0.0180021390861626" />
        </inertial>
        <visual>
        <origin
            xyz="0 0 0"
            rpy="0 0 0" />
        <geometry>
            <mesh
            filename="package://owr_bluetounge_tf/meshes/back_left_wheel.STL" />
        </geometry>
        <material
            name="">
            <color
            rgba="0.647058823529412 0.619607843137255 0.588235294117647 1" />
        </material>
        </visual>
        <collision>
        <origin
            xyz="0 0 0"
            rpy="0 0 0" />
        <geometry>
            <mesh
            filename="package://owr_bluetounge_tf/meshes/back_left_wheel.STL" />
        </geometry>
        </collision>
    </link>
    <joint
        name="back_left_wheel_axel"
        type="continuous">
        <origin
        xyz="-0.0254000000000002 0.0235 0.26363"
        rpy="3.14159265358979 0 0" />
        <parent
        link="back_left_bogey" />
        <child
        link="back_left_wheel" />
        <axis
        xyz="0 0 1" />
    </joint>
    <link
        name="arm_lazy_susan">
        <inertial>
        <origin
            xyz="-5.55111512312578E-17 0.0103586865525113 -0.00420870803741594"
            rpy="0 0 0" />
        <mass
            value="2.70088597742169" />
        <inertia
            ixx="0.0152038238511852"
            ixy="-1.16009632455949E-17"
            ixz="3.11708124589583E-18"
            iyy="0.0200726983344031"
            iyz="-0.0017155575507279"
            izz="0.0146406652102539" />
        </inertial>
        <visual>
        <origin
            xyz="0 0 0"
            rpy="0 0 0" />
        <geometry>
            <mesh
            filename="package://owr_bluetounge_tf/meshes/arm_lazy_susan.STL" />
        </geometry>
        <material
            name="">
            <color
            rgba="0.866666666666667 0.909803921568627 1 1" />
        </material>
        </visual>
        <collision>
        <origin
            xyz="0 0 0"
            rpy="0 0 0" />
        <geometry>
            <mesh
            filename="package://owr_bluetounge_tf/meshes/arm_lazy_susan.STL" />
        </geometry>
        </collision>
    </link>
    <joint
        name="lazy_susan"
        type="fixed">
        <origin
        xyz="0.169785783391727 0.0946602235783251 0.0966852619267727"
        rpy="1.5707963267949 6.12303176911189E-17 1.5707963267949" />
        <parent
        link="robot_base" />
        <child
        link="arm_lazy_susan" />
        <axis
        xyz="0 0 0" />
    </joint>
    <link
        name="linear_base_top">
        <inertial>
        <origin
            xyz="-0.00827305776054969 0.108157241381836 -0.0088903802654173"
            rpy="0 0 0" />
        <mass
            value="0.505108110191142" />
        <inertia
            ixx="0.00374185573491988"
            ixy="-0.000927476667041981"
            ixz="1.28969205871129E-10"
            iyy="0.00054160221099784"
            iyz="-1.0733416157496E-09"
            izz="0.00415524012603247" />
        </inertial>
        <visual>
        <origin
            xyz="0 0 0"
            rpy="0 0 0" />
        <geometry>
            <mesh
            filename="package://owr_bluetounge_tf/meshes/linear_base_top.STL" />
        </geometry>
        <material
            name="">
            <color
            rgba="1 1 1 1" />
        </material>
        </visual>
        <collision>
        <origin
            xyz="0 0 0"
            rpy="0 0 0" />
        <geometry>
            <mesh
            filename="package://owr_bluetounge_tf/meshes/linear_base_top.STL" />
        </geometry>
        </collision>
    </link>
    <joint
        name="top_linear_rotate"
        type="fixed">
        <origin
        xyz="0.00888999999999932 0.209155716713238 -0.0898381894927386"
        rpy="0 1.5707963267949 0" />
        <parent
        link="arm_lazy_susan" />
        <child
        link="linear_base_top" />
        <axis
        xyz="0 0 0" />
    </joint>
    <link
        name="linear_top_top">
        <inertial>
        <origin
            xyz="-6.37512356793657E-09 0.141281566903566 1.01211753700259E-08"
            rpy="0 0 0" />
        <mass
            value="0.707194764669469" />
        <inertia
            ixx="0.00473421933672359"
            ixy="-5.16467243572744E-10"
            ixz="-3.86693268027555E-11"
            iyy="3.53245823073806E-05"
            iyz="7.77593049458533E-10"
            izz="0.00473445875575522" />
        </inertial>
        <visual>
        <origin
            xyz="0 0 0"
            rpy="0 0 0" />
        <geometry>
            <mesh
            filename="package://owr_bluetounge_tf/meshes/linear_top_top.STL" />
        </geometry>
        <material
            name="">
            <color
            rgba="0.647058823529412 0.619607843137255 0.588235294117647 1" />
        </material>
        </visual>
        <collision>
        <origin
            xyz="0 0 0"
            rpy="0 0 0" />
        <geometry>
            <mesh
            filename="package://owr_bluetounge_tf/meshes/linear_top_top.STL" />
        </geometry>
        </collision>
    </link>
    <joint
        name="linear_actuator_top"
        type="fixed">
        <origin
        xyz="-0.00981439732623338 0.0529180728395591 -0.00889040000000024"
        rpy="1.38777878078145E-15 1.57772181044202E-30 0.183380371627217" />
        <parent
        link="linear_base_top" />
        <child
        link="linear_top_top" />
        <axis
        xyz="0 0 0" />
    </joint>
    <link
        name="arm_upper_plate">
        <inertial>
        <origin
            xyz="0.303825861593075 0.0669622688080408 0.0457419018257636"
            rpy="0 0 0" />
        <mass
            value="0.619350379927045" />
        <inertia
            ixx="0.00288749250376705"
            ixy="0.00193134432626355"
            ixz="4.85675369085583E-05"
            iyy="0.0162631439417548"
            iyz="1.07041331003076E-05"
            izz="0.0167683575566276" />
        </inertial>
        <visual>
        <origin
            xyz="0 0 0"
            rpy="0 0 0" />
        <geometry>
            <mesh
            filename="package://owr_bluetounge_tf/meshes/arm_upper_plate.STL" />
        </geometry>
        <material
            name="">
            <color
            rgba="0.866666666666667 0.909803921568627 1 1" />
        </material>
        </visual>
        <collision>
        <origin
            xyz="0 0 0"
            rpy="0 0 0" />
        <geometry>
            <mesh
            filename="package://owr_bluetounge_tf/meshes/arm_upper_plate.STL" />
        </geometry>
        </collision>
    </link>
    <joint
        name="arm_upper_plate_joint"
        type="fixed">
        <origin
        xyz="-0.0870975284299248 -0.181697727038711 0.046000400000001"
        rpy="-3.14159265358979 1.36955627252896E-15 1.73302787706139" />
        <parent
        link="linear_top_top" />
        <child
        link="arm_upper_plate" />
        <axis
        xyz="0 0 0" />
    </joint>
    <link
        name="linear_bottom">
        <inertial>
        <origin
            xyz="-0.0949577434319117 -0.271420460274935 0.16075756080638"
            rpy="0 0 0" />
        <mass
            value="0.536595945710244" />
        <inertia
            ixx="0.00612660718464707"
            ixy="-1.71365197308669E-05"
            ixz="2.95648636793797E-06"
            iyy="0.00055531865385143"
            iyz="-0.00118286224819541"
            izz="0.00570419649343337" />
        </inertial>
        <visual>
        <origin
            xyz="0 0 0"
            rpy="0 0 0" />
        <geometry>
            <mesh
            filename="package://owr_bluetounge_tf/meshes/linear_bottom.STL" />
        </geometry>
        <material
            name="">
            <color
            rgba="0.647058823529412 0.619607843137255 0.588235294117647 1" />
        </material>
        </visual>
        <collision>
        <origin
            xyz="0 0 0"
            rpy="0 0 0" />
        <geometry>
            <mesh
            filename="package://owr_bluetounge_tf/meshes/linear_bottom.STL" />
        </geometry>
        </collision>
    </link>
    <joint
        name="linear_bottom_rotate"
        type="fixed">
        <origin
        xyz="-0.0946602235783251 -0.0966852619267727 -0.169785783391727"
        rpy="0 0 3.14159265358979" />
        <parent
        link="arm_lazy_susan" />
        <child
        link="linear_bottom" />
        <axis
        xyz="0 0 0" />
    </joint>
    <link
        name="linear_bottom_top">
        <inertial>
        <origin
            xyz="-6.33457777898805E-09 0.16682085154449 1.32825593231328E-05"
            rpy="0 0 0" />
        <mass
            value="0.835207341590641" />
        <inertia
            ixx="0.00778103255092761"
            ixy="-7.13429649116244E-10"
            ixz="-4.02800376428866E-11"
            iyy="4.18322602778582E-05"
            iyz="1.78264194189716E-06"
            izz="0.00778112287567495" />
        </inertial>
        <visual>
        <origin
            xyz="0 0 0"
            rpy="0 0 0" />
        <geometry>
            <mesh
            filename="package://owr_bluetounge_tf/meshes/linear_bottom_top.STL" />
        </geometry>
        <material
            name="">
            <color
            rgba="0.647058823529412 0.619607843137255 0.588235294117647 1" />
        </material>
        </visual>
        <collision>
        <origin
            xyz="0 0 0"
            rpy="0 0 0" />
        <geometry>
            <mesh
            filename="package://owr_bluetounge_tf/meshes/linear_bottom_top.STL" />
        </geometry>
        </collision>
    </link>
    <joint
        name="linear_bottom_joint"
        type="fixed">
        <origin
        xyz="-0.0946598235783247 -0.394525039857631 0.186688374751556"
        rpy="1.5707963267949 1.27763206823209 -1.5707963267949" />
        <parent
        link="linear_bottom" />
        <child
        link="linear_bottom_top" />
        <axis
        xyz="0 0 0" />
    </joint>
    <link
        name="arm_fibbia">
        <inertial>
        <origin
            xyz="-0.111229606598178 -0.0113074805440442 0.0219749264705172"
            rpy="0 0 0" />
        <mass
            value="0.442121814661083" />
        <inertia
            ixx="0.000366096382112353"
            ixy="-0.0005354095669459"
            ixz="-2.56330837246391E-06"
            iyy="0.0101826418453219"
            iyz="3.73500255788405E-07"
            izz="0.0101895791265052" />
        </inertial>
        <visual>
        <origin
            xyz="0 0 0"
            rpy="0 0 0" />
        <geometry>
            <mesh
            filename="package://owr_bluetounge_tf/meshes/arm_fibbia.STL" />
        </geometry>
        <material
            name="">
            <color
            rgba="0.2 0.4 0.698039215686274 1" />
        </material>
        </visual>
        <collision>
        <origin
            xyz="0 0 0"
            rpy="0 0 0" />
        <geometry>
            <mesh
            filename="package://owr_bluetounge_tf/meshes/arm_fibbia.STL" />
        </geometry>
        </collision>
    </link>
    <joint
        name="arm_fibbia_actuator_joint"
        type="fixed">
        <origin
        xyz="-0.118549467334927 0.278839840371506 -0.0219995999999992"
        rpy="4.90521813985624E-15 1.8888839732129E-15 0.74850233700259" />
        <parent
        link="linear_bottom_top" />
        <child
        link="arm_fibbia" />
        <axis
        xyz="0 0 0" />
    </joint>
    <link
        name="arm_triangle">
        <inertial>
        <origin
            xyz="-0.426157828373 -0.62305598804171 -0.0946602235783259"
            rpy="0 0 0" />
        <mass
            value="0.12928420888469" />
        <inertia
            ixx="0.000210500994705606"
            ixy="5.16690097825123E-18"
            ixz="1.39533853190394E-17"
            iyy="0.000300209978678872"
            iyz="-8.86103478776468E-18"
            izz="0.000206138452596922" />
        </inertial>
        <visual>
        <origin
            xyz="0 0 0"
            rpy="0 0 0" />
        <geometry>
            <mesh
            filename="package://owr_bluetounge_tf/meshes/arm_triangle.STL" />
        </geometry>
        <material
            name="">
            <color
            rgba="0.866666666666667 0.909803921568627 1 1" />
        </material>
        </visual>
        <collision>
        <origin
            xyz="0 0 0"
            rpy="0 0 0" />
        <geometry>
            <mesh
            filename="package://owr_bluetounge_tf/meshes/arm_triangle.STL" />
        </geometry>
        </collision>
    </link>
    <joint
        name="arm_triangle"
        type="fixed">
        <origin
        xyz="-0.349235472956231 -0.645293718143375 -0.0726602235783218"
        rpy="3.14159265358979 -6.23289436518305E-15 -1.11578202661211" />
        <parent
        link="arm_fibbia" />
        <child
        link="arm_triangle" />
        <axis
        xyz="0 0 0" />
    </joint>
    <link
        name="arm_tibbia">
        <inertial>
        <origin
            xyz="0.0480000000000006 -0.149558927744742 0.0865975206579046"
            rpy="0 0 0" />
        <mass
            value="0.222440263368329" />
        <inertia
            ixx="0.00384135136405409"
            ixy="-1.51788304147971E-17"
            ixz="1.73472347597681E-18"
            iyy="0.00137653776894159"
            iyz="-0.00164919981045544"
            izz="0.0032698825606534" />
        </inertial>
        <visual>
        <origin
            xyz="0 0 0"
            rpy="0 0 0" />
        <geometry>
            <mesh
            filename="package://owr_bluetounge_tf/meshes/arm_tibbia.STL" />
        </geometry>
        <material
            name="">
            <color
            rgba="0.647058823529412 0.619607843137255 0.588235294117647 1" />
        </material>
        </visual>
        <collision>
        <origin
            xyz="0 0 0"
            rpy="0 0 0" />
        <geometry>
            <mesh
            filename="package://owr_bluetounge_tf/meshes/arm_tibbia.STL" />
        </geometry>
        </collision>
    </link>
    <joint
        name="arm_tibbia_joint"
        type="fixed">
        <origin
        xyz="-0.481157828372991 -0.639792979669676 -0.0466602235783267"
        rpy="3.06747722254308 1.5707963267949 0" />
        <parent
        link="arm_triangle" />
        <child
        link="arm_tibbia" />
        <axis
        xyz="0 0 0" />
    </joint>
    <link
        name="claw_base">
        <inertial>
        <origin
            xyz="0.0487247088252122 -0.0323817240194191 -0.00839635607805789"
            rpy="0 0 0" />
        <mass
            value="0.190644078038689" />
        <inertia
            ixx="0.000189726782800824"
            ixy="-4.7844788782777E-09"
            ixz="2.29062364797535E-06"
            iyy="0.000279038001579714"
            iyz="2.3311212335571E-05"
            izz="0.000210943055384216" />
        </inertial>
        <visual>
        <origin
            xyz="0 0 0"
            rpy="0 0 0" />
        <geometry>
            <mesh
            filename="package://owr_bluetounge_tf/meshes/claw_base.STL" />
        </geometry>
        <material
            name="">
            <color
            rgba="0.647058823529412 0.619607843137255 0.588235294117647 1" />
        </material>
        </visual>
        <collision>
        <origin
            xyz="0 0 0"
            rpy="0 0 0" />
        <geometry>
            <mesh
            filename="package://owr_bluetounge_tf/meshes/claw_base.STL" />
        </geometry>
        </collision>
    </link>
    <joint
        name="claw_base_joint"
        type="fixed">
        <origin
        xyz="0 -0.335644754718405 0.194344824603542"
        rpy="0 0 0" />
        <parent
        link="arm_tibbia" />
        <child
        link="claw_base" />
        <axis
        xyz="0 0 0" />
    </joint>
    <link
        name="claw_wrist">
        <inertial>
        <origin
            xyz="-0.0757797816972197 0.00704218921920291 0.00607338903901146"
            rpy="0 0 0" />
        <mass
            value="0.0966802947359476" />
        <inertia
            ixx="4.8636170619783E-05"
            ixy="-2.9149526623362E-05"
            ixz="-2.24214463919015E-05"
            iyy="0.000252808254588153"
            iyz="9.17967825748088E-06"
            izz="0.000242760290274756" />
        </inertial>
        <visual>
        <origin
            xyz="0 0 0"
            rpy="0 0 0" />
        <geometry>
            <mesh
            filename="package://owr_bluetounge_tf/meshes/claw_wrist.STL" />
        </geometry>
        <material
            name="">
            <color
            rgba="0.898039215686275 0.92156862745098 0.929411764705882 1" />
        </material>
        </visual>
        <collision>
        <origin
            xyz="0 0 0"
            rpy="0 0 0" />
        <geometry>
            <mesh
            filename="package://owr_bluetounge_tf/meshes/claw_wrist.STL" />
        </geometry>
        </collision>
    </link>
    <joint
        name="claw_wrist_rotate"
        type="fixed">
        <origin
        xyz="0.0480003841815951 -0.0709789830059453 -0.0130337434259741"
        rpy="1.67477680654928 1.50082202242134 -1.5707963267949" />
        <parent
        link="claw_base" />
        <child
        link="claw_wrist" />
        <axis
        xyz="0 0 0" />
    </joint>
    <link
        name="claw_r_clip">
        <inertial>
        <origin
            xyz="0.00499964697817903 -0.00147495288215918 -0.0150000754069793"
            rpy="0 0 0" />
        <mass
            value="0.00233424454841112" />
        <inertia
            ixx="2.01603074490562E-07"
            ixy="-9.01072470537812E-13"
            ixz="1.45353563114414E-13"
            iyy="1.74108213804167E-07"
            iyz="3.73298286917451E-13"
            izz="6.24950197273603E-08" />
        </inertial>
        <visual>
        <origin
            xyz="0 0 0"
            rpy="0 0 0" />
        <geometry>
            <mesh
            filename="package://owr_bluetounge_tf/meshes/claw_r_clip.STL" />
        </geometry>
        <material
            name="">
            <color
            rgba="0.898039215686275 0.92156862745098 0.929411764705882 1" />
        </material>
        </visual>
        <collision>
        <origin
            xyz="0 0 0"
            rpy="0 0 0" />
        <geometry>
            <mesh
            filename="package://owr_bluetounge_tf/meshes/claw_r_clip.STL" />
        </geometry>
        </collision>
    </link>
    <joint
        name="claw_r_clip"
        type="fixed">
        <origin
        xyz="-0.122500337748276 0.00319226604832362 0.0498174063263954"
        rpy="2.71212000512914 -1.318871613132 0.417457472625823" />
        <parent
        link="claw_wrist" />
        <child
        link="claw_r_clip" />
        <axis
        xyz="0 0 0" />
    </joint>
    <link
        name="claw_clamp_right">
        <inertial>
        <origin
            xyz="-0.0315370095814033 0.0189678067426234 -0.00799999999986689"
            rpy="0 0 0" />
        <mass
            value="0.0072956721263419" />
        <inertia
            ixx="2.87193402105979E-06"
            ixy="-7.10128298441632E-08"
            ixz="4.5109732126505E-21"
            iyy="1.02077380019071E-06"
            iyz="1.12713306953119E-20"
            izz="3.87325269558026E-06" />
        </inertial>
        <visual>
        <origin
            xyz="0 0 0"
            rpy="0 0 0" />
        <geometry>
            <mesh
            filename="package://owr_bluetounge_tf/meshes/claw_clamp_right.STL" />
        </geometry>
        <material
            name="">
            <color
            rgba="0.898039215686275 0.92156862745098 0.929411764705882 1" />
        </material>
        </visual>
        <collision>
        <origin
            xyz="0 0 0"
            rpy="0 0 0" />
        <geometry>
            <mesh
            filename="package://owr_bluetounge_tf/meshes/claw_clamp_right.STL" />
        </geometry>
        </collision>
    </link>
    <joint
        name="claw_clamp_right"
        type="fixed">
        <origin
        xyz="-0.0351647666535667 -0.00999999999986573 -0.00950788029785021"
        rpy="-1.5707963267949 -0.619467829681 -3.14159265358979" />
        <parent
        link="claw_r_clip" />
        <child
        link="claw_clamp_right" />
        <axis
        xyz="0 0 0" />
    </joint>
    <link
        name="claw_gear_right">
        <inertial>
        <origin
            xyz="0.00506177139731656 -0.00552974505856529 -0.011557123761874"
            rpy="0 0 0" />
        <mass
            value="0.00212265528368017" />
        <inertia
            ixx="1.1620179181382E-07"
            ixy="-5.5100076844545E-08"
            ixz="-7.9419209686153E-10"
            iyy="1.76334443812444E-07"
            iyz="5.45280732455247E-10"
            izz="2.83571413774914E-07" />
        </inertial>
        <visual>
        <origin
            xyz="0 0 0"
            rpy="0 0 0" />
        <geometry>
            <mesh
            filename="package://owr_bluetounge_tf/meshes/claw_gear_right.STL" />
        </geometry>
        <material
            name="">
            <color
            rgba="0.650980392156863 0.619607843137255 0.588235294117647 1" />
        </material>
        </visual>
        <collision>
        <origin
            xyz="0 0 0"
            rpy="0 0 0" />
        <geometry>
            <mesh
            filename="package://owr_bluetounge_tf/meshes/claw_gear_right.STL" />
        </geometry>
        </collision>
    </link>
    <joint
        name="claw_gear_right"
        type="fixed">
        <origin
        xyz="-0.139770808859842 0.00980927262252407 0.0168794851239742"
        rpy="-1.83894270456153 1.16825856833071 -0.247613761933362" />
        <parent
        link="claw_wrist" />
        <child
        link="claw_gear_right" />
        <axis
        xyz="0 0 0" />
    </joint>
    <link
        name="claw_left_gear">
        <inertial>
        <origin
            xyz="-0.00674277746024721 -0.00164188914532973 -0.00715936645088167"
            rpy="0 0 0" />
        <mass
            value="0.00330562082363482" />
        <inertia
            ixx="2.17193475397135E-07"
            ixy="-8.87582996738852E-08"
            ixz="-1.92308627458653E-08"
            iyy="2.82815271138563E-07"
            iyz="3.20792874131889E-08"
            izz="4.02938220008641E-07" />
        </inertial>
        <visual>
        <origin
            xyz="0 0 0"
            rpy="0 0 0" />
        <geometry>
            <mesh
            filename="package://owr_bluetounge_tf/meshes/claw_left_gear.STL" />
        </geometry>
        <material
            name="">
            <color
            rgba="0.650980392156863 0.619607843137255 0.588235294117647 1" />
        </material>
        </visual>
        <collision>
        <origin
            xyz="0 0 0"
            rpy="0 0 0" />
        <geometry>
            <mesh
            filename="package://owr_bluetounge_tf/meshes/claw_left_gear.STL" />
        </geometry>
        </collision>
    </link>
    <joint
        name="claw_left_gear"
        type="fixed">
        <origin
        xyz="-0.126692000000001 0.00393201488198414 -0.0195681216649714"
        rpy="-1.67482767238228 0.0312161138395368 -0.00325867964804768" />
        <parent
        link="claw_wrist" />
        <child
        link="claw_left_gear" />
        <axis
        xyz="0 0 0" />
    </joint>
    <link
        name="claw_left_grip">
        <inertial>
        <origin
            xyz="0.0117618019587442 -0.0345244765346477 -0.00524012259488826"
            rpy="0 0 0" />
        <mass
            value="0.00962991667475299" />
        <inertia
            ixx="4.8140428252377E-06"
            ixy="-1.6529187507395E-06"
            ixz="1.70595505742753E-08"
            iyy="1.90619728239485E-06"
            iyz="-3.08980035097402E-08"
            izz="6.60982134407743E-06" />
        </inertial>
        <visual>
        <origin
            xyz="0 0 0"
            rpy="0 0 0" />
        <geometry>
            <mesh
            filename="package://owr_bluetounge_tf/meshes/claw_left_grip.STL" />
        </geometry>
        <material
            name="">
            <color
            rgba="0.650980392156863 0.619607843137255 0.588235294117647 1" />
        </material>
        </visual>
        <collision>
        <origin
            xyz="0 0 0"
            rpy="0 0 0" />
        <geometry>
            <mesh
            filename="package://owr_bluetounge_tf/meshes/claw_left_grip.STL" />
        </geometry>
        </collision>
    </link>
    <joint
        name="claw_left_grip"
        type="fixed">
        <origin
        xyz="-0.126692000000001 -0.000723688290788171 -0.056232921582154"
        rpy="3.14158226481859 -1.46681584600206 1.5707964703522" />
        <parent
        link="claw_wrist" />
        <child
        link="claw_left_grip" />
        <axis
        xyz="0 0 0" />
    </joint>
    <link
        name="arm_lower">
        <inertial>
        <origin
            xyz="0.407921186378514 -0.107924458009344 -0.0946602235783255"
            rpy="0 0 0" />
        <mass
            value="0.503679894640802" />
        <inertia
            ixx="0.000808456384558003"
            ixy="-0.00158918881897295"
            ixz="-4.2326337835323E-17"
            iyy="0.0163167890705872"
            iyz="3.72502740876499E-18"
            izz="0.0163341322339627" />
        </inertial>
        <visual>
        <origin
            xyz="0 0 0"
            rpy="0 0 0" />
        <geometry>
            <mesh
            filename="package://owr_bluetounge_tf/meshes/arm_lower.STL" />
        </geometry>
        <material
            name="">
            <color
            rgba="0.866666666666667 0.909803921568627 1 1" />
        </material>
        </visual>
        <collision>
        <origin
            xyz="0 0 0"
            rpy="0 0 0" />
        <geometry>
            <mesh
            filename="package://owr_bluetounge_tf/meshes/arm_lower.STL" />
        </geometry>
        </collision>
    </link>
    <joint
        name="arm_lower_joint"
        type="fixed">
        <origin
        xyz="-0.349235472956231 -0.645293718143375 -0.0726602235783218"
        rpy="3.14159265358979 5.34720995256263E-15 0.879804291107628" />
        <parent
        link="arm_fibbia" />
        <child
        link="arm_lower" />
        <axis
        xyz="0 0 0" />
    </joint>
    <link
        name="right_bogey">
        <inertial>
        <origin
            xyz="0.00702330620181487 0.401103543187842 0.203839639805084"
            rpy="0 0 0" />
        <mass
            value="4.05061648092413" />
        <inertia
            ixx="0.351121012651337"
            ixy="-0.00445903467915979"
            ixz="0.00098479921686118"
            iyy="0.0388497685294275"
            iyz="-0.00612993465614441"
            izz="0.348769355517416" />
        </inertial>
        <visual>
        <origin
            xyz="0 0 0"
            rpy="0 0 0" />
        <geometry>
            <mesh
            filename="package://owr_bluetounge_tf/meshes/right_bogey.STL" />
        </geometry>
        <material
            name="">
            <color
            rgba="0.647058823529412 0.619607843137255 0.588235294117647 1" />
        </material>
        </visual>
        <collision>
        <origin
            xyz="0 0 0"
            rpy="0 0 0" />
        <geometry>
            <mesh
            filename="package://owr_bluetounge_tf/meshes/right_bogey.STL" />
        </geometry>
        </collision>
    </link>
    <joint
        name="right_axel"
        type="fixed">
        <origin
        xyz="-0.00272585567995524 0.000759911601109694 0.0335572619267736"
        rpy="-1.5707963267949 0.994042112655132 -3.14159265358979" />
        <parent
        link="robot_base" />
        <child
        link="right_bogey" />
        <axis
        xyz="0 0 0" />
    </joint>
    <link
        name="front_right_wheel">
        <inertial>
        <origin
            xyz="-0.0664896050266992 0 2.96170694409348E-05"
            rpy="0 0 0" />
        <mass
            value="2.15472811624945" />
        <inertia
            ixx="0.0180021390861626"
            ixy="-1.24152644906478E-18"
            ixz="-1.0153494159279E-06"
            iyy="0.0154723847547672"
            iyz="-7.89148838948519E-21"
            izz="0.0154727320555494" />
        </inertial>
        <visual>
        <origin
            xyz="0 0 0"
            rpy="0 0 0" />
        <geometry>
            <mesh
            filename="package://owr_bluetounge_tf/meshes/front_right_wheel.STL" />
        </geometry>
        <material
            name="">
            <color
            rgba="0.294117647058824 0.294117647058824 0.294117647058824 1" />
        </material>
        </visual>
        <collision>
        <origin
            xyz="0 0 0"
            rpy="0 0 0" />
        <geometry>
            <mesh
            filename="package://owr_bluetounge_tf/meshes/front_right_wheel.STL" />
        </geometry>
        </collision>
    </link>
    <joint
        name="front_right_wheel_axel"
        type="continuous">
        <origin
        xyz="0.131047529535391 0.682426121888892 0.30766"
        rpy="0.57675421413977 -1.5707963267949 0" />
        <parent
        link="right_bogey" />
        <child
        link="front_right_wheel" />
        <axis
        xyz="1 0 0" />
    </joint>
    <link
        name="back_right_bogey">
        <inertial>
        <origin
            xyz="-0.134236970084978 -0.193507260305609 0.273682251144367"
            rpy="0 0 0" />
        <mass
            value="2.46052661051461" />
        <inertia
            ixx="0.154363056002661"
            ixy="-0.000844974684652335"
            ixz="-1.7891058444345E-05"
            iyy="0.132955020392286"
            iyz="0.000381750018593088"
            izz="0.0513773755705077" />
        </inertial>
        <visual>
        <origin
            xyz="0 0 0"
            rpy="0 0 0" />
        <geometry>
            <mesh
            filename="package://owr_bluetounge_tf/meshes/back_right_bogey.STL" />
        </geometry>
        <material
            name="">
            <color
            rgba="0.898039215686275 0.917647058823529 0.929411764705882 1" />
        </material>
        </visual>
        <collision>
        <origin
            xyz="0 0 0"
            rpy="0 0 0" />
        <geometry>
            <mesh
            filename="package://owr_bluetounge_tf/meshes/back_right_bogey.STL" />
        </geometry>
        </collision>
    </link>
    <joint
        name="back_right_bogey_axel"
        type="fixed">
        <origin
        xyz="0.714828885819377 -0.161773416923871 0.373659999999994"
        rpy="2.14755054093466 -1.5707963267949 3.14159265359" />
        <parent
        link="right_bogey" />
        <child
        link="back_right_bogey" />
        <axis
        xyz="0 0 0" />
    </joint>
    <link
        name="middle_right_wheel">
        <inertial>
        <origin
            xyz="-0.0664896050266993 -1.73472347597681E-18 2.96170694409903E-05"
            rpy="0 0 0" />
        <mass
            value="2.15472811624945" />
        <inertia
            ixx="0.0180021390861626"
            ixy="-1.36198209947543E-18"
            ixz="-1.01534941592839E-06"
            iyy="0.0154723847547672"
            iyz="-3.44368330266956E-21"
            izz="0.0154727320555494" />
        </inertial>
        <visual>
        <origin
            xyz="0 0 0"
            rpy="0 0 0" />
        <geometry>
            <mesh
            filename="package://owr_bluetounge_tf/meshes/middle_right_wheel.STL" />
        </geometry>
        <material
            name="">
            <color
            rgba="0.294117647058824 0.294117647058824 0.294117647058824 1" />
        </material>
        </visual>
        <collision>
        <origin
            xyz="0 0 0"
            rpy="0 0 0" />
        <geometry>
            <mesh
            filename="package://owr_bluetounge_tf/meshes/middle_right_wheel.STL" />
        </geometry>
        </collision>
    </link>
    <joint
        name="middle_right_wheel_axel"
        type="continuous">
        <origin
        xyz="-0.0659999999999967 -0.0289999999999251 0.5253999999999"
        rpy="-1.57079632679489 -1.3363823550461E-45 2.40741243048404E-31" />
        <parent
        link="back_right_bogey" />
        <child
        link="middle_right_wheel" />
        <axis
        xyz="1 0 0" />
    </joint>
    <link
        name="back_right_wheel">
        <inertial>
        <origin
            xyz="-0.0664896050266992 0 2.96170694410458E-05"
            rpy="0 0 0" />
        <mass
            value="2.15472811624945" />
        <inertia
            ixx="0.0180021390861626"
            ixy="-2.00472611016956E-18"
            ixz="-1.01534941592787E-06"
            iyy="0.0154723847547672"
            iyz="-5.86561588921519E-21"
            izz="0.0154727320555494" />
        </inertial>
        <visual>
        <origin
            xyz="0 0 0"
            rpy="0 0 0" />
        <geometry>
            <mesh
            filename="package://owr_bluetounge_tf/meshes/back_right_wheel.STL" />
        </geometry>
        <material
            name="">
            <color
            rgba="0.294117647058824 0.294117647058824 0.294117647058824 1" />
        </material>
        </visual>
        <collision>
        <origin
            xyz="0 0 0"
            rpy="0 0 0" />
        <geometry>
            <mesh
            filename="package://owr_bluetounge_tf/meshes/back_right_wheel.STL" />
        </geometry>
        </collision>
    </link>
    <joint
        name="back_right_wheel_axel"
        type="continuous">
        <origin
        xyz="-0.066 -0.029 0.0253999999999999"
        rpy="-1.57079632679489 0 0" />
        <parent
        link="back_right_bogey" />
        <child
        link="back_right_wheel" />
        <axis
        xyz="1 0 0" />
    </joint>
    
    
    <link
        name="laser_tilt_base">
        <inertial>
        <origin
            xyz="0.43736 -0.0070195 0.04262"
            rpy="0 0 0" />
        <mass
            value="0.060913" />
        <inertia
            ixx="5.6809E-05"
            ixy="-3.1933E-07"
            ixz="-4.1287E-07"
            iyy="4.2988E-05"
            iyz="1.9097E-05"
            izz="3.5802E-05" />
        </inertial>
        <visual>
        <origin
            xyz="0 0 0"
            rpy="0 0 0" />
        <geometry>
            <mesh
            filename="package://owr_bluetounge_tf/meshes/laser_tilt_base.STL" />
        </geometry>
        <material
            name="">
            <color
            rgba="0.79216 0.81961 0.93333 1" />
        </material>
        </visual>
        <collision>
        <origin
            xyz="0 0 0"
            rpy="0 0 0" />
        <geometry>
            <mesh
            filename="package://owr_bluetounge_tf/meshes/laser_tilt_base.STL" />
        </geometry>
        </collision>
    </link>
    <joint name="laser_tilt_robot_base" type="fixed">
        <axis xyz="0 0 0" />
        <origin xyz=".245 0.28 0.145 " rpy="0.785398 0 -1.5708"/>
        <parent link="robot_base"/>
        <child link="laser_tilt_base"/>
    </joint>
    <link
        name="laser_tilt_tilt">
        <inertial>
        <origin
            xyz="0.027266 0.024274 -0.0025636"
            rpy="0 0 0" />
        <mass
            value="0.060855" />
        <inertia
            ixx="4.334E-05"
            ixy="1.9349E-06"
            ixz="-1.9524E-07"
            iyy="3.4772E-05"
            iyz="-2.8452E-07"
            izz="3.9596E-05" />
        </inertial>
        <visual>
        <origin
            xyz="0 0 0"
            rpy="0 0 0" />
        <geometry>
            <mesh
            filename="package://owr_bluetounge_tf/meshes/laser_tilt_tilt.STL" />
        </geometry>
        <material
            name="">
            <color
            rgba="0.79216 0.81961 0.93333 1" />
        </material>
        </visual>
        <collision>
        <origin
            xyz="0 0 0"
            rpy="0 0 0" />
        <geometry>
            <mesh
            filename="package://owr_bluetounge_tf/meshes/laser_tilt_tilt.STL" />
        </geometry>
        </collision>
    </link>
    <joint
        name="laser_tilt_joint"
        type="continuous">
        <origin
        xyz="0.3929 -0.01446 -0.014263"
        rpy="0.82137 0 0" />
        <parent
        link="laser_tilt_base" />
        <child
        link="laser_tilt_tilt" />
        <axis
        xyz="-1 0 0" />
    </joint>

    <include filename="$(find hector_sensors_description)/urdf/hokuyo_utm30lx.urdf.xacro" /> 
    <xacro:hokuyo_utm30lx_gpu name="laser" ros_topic="/laser/scan" update_rate="40" ray_count="1440" min_angle="-2.35619" max_angle="2.35619" parent="laser_tilt_tilt">
        <origin xyz="0.02 0.1 0" rpy="-1.6708 0 0"/>
    </xacro:hokuyo_utm30lx_gpu>
    <!--<joint name="hokuyo_joint" type="fixed">
        <axis xyz="0 0 0" />
        <origin xyz="0.04 0.08 0" rpy="-1.5708 0 0"/>
        <parent link="laser_tilt_tilt"/>
        <child link="laser"/>
    </joint>-->

    <!-- Hokuyo Laser -->
    <!--<link name="laser">
        <collision>
        <origin xyz="0 0 0" rpy="0 0 0"/>
        <geometry>
        <box size="0.1 0.1 0.1"/>
        </geometry>
        </collision>

        <visual>
        <origin xyz="0 0 0" rpy="0 0 0"/>
        <geometry>
            <mesh filename="package://owr_bluetounge_tf/meshes/hokuyo.dae"/>
        </geometry>
        </visual>

        <inertial>
        <mass value="1e-5" />
        <origin xyz="0 0 0" rpy="0 0 0"/>
        <inertia ixx="1e-6" ixy="0" ixz="0" iyy="1e-6" iyz="0" izz="1e-6" />
        </inertial>
    </link>-->
    <!--
    ####################GAZEBO SIMULATOR STUFF#########################
    -->

    <!-- Joints -->
    <xacro:property name="gearbox_mechReduction" value="10" />
    <transmission name="front_left_wheel_axel">
        <type>transmission_interface/SimpleTransmission</type>
        <joint name="front_left_wheel_axel">
        <hardwareInterface>VelocityJointInterface</hardwareInterface>
        </joint>
        <actuator name="front_left_wheel_motor">
        <mechanicalReduction>${gearbox_mechReduction}</mechanicalReduction>
        <hardwareInterface>VelocityJointInterface</hardwareInterface>
        </actuator>
    </transmission>
    <transmission name="middle_left_wheel_axel">
        <type>transmission_interface/SimpleTransmission</type>
        <joint name="middle_left_wheel_axel">
        <hardwareInterface>VelocityJointInterface</hardwareInterface>
        </joint>
        <actuator name="middle_left_wheel_motor">
        <mechanicalReduction>${gearbox_mechReduction}</mechanicalReduction>
        <hardwareInterface>VelocityJointInterface</hardwareInterface>
        </actuator>
    </transmission>
    <transmission name="back_left_wheel_axel">
        <type>transmission_interface/SimpleTransmission</type>
        <joint name="back_left_wheel_axel">
                <hardwareInterface>VelocityJointInterface</hardwareInterface>
        </joint>
        <actuator name="back_left_wheel_motor">
        <mechanicalReduction>${gearbox_mechReduction}</mechanicalReduction>
        <hardwareInterface>VelocityJointInterface</hardwareInterface>
        </actuator>
    </transmission>
    <transmission name="front_right_wheel_axel">
        <type>transmission_interface/SimpleTransmission</type>
        <joint name="front_right_wheel_axel">
        <hardwareInterface>VelocityJointInterface</hardwareInterface>
        </joint>
        <actuator name="front_right_wheel_motor">
        <mechanicalReduction>${gearbox_mechReduction}</mechanicalReduction>
        <hardwareInterface>VelocityJointInterface</hardwareInterface>
        </actuator>
    </transmission>
    <transmission name="middle_right_wheel_axel">
        <type>transmission_interface/SimpleTransmission</type>
        <joint name="middle_right_wheel_axel">
            <hardwareInterface>VelocityJointInterface</hardwareInterface>
        </joint>
        <actuator name="middle_right_wheel_motor">
        <mechanicalReduction>${gearbox_mechReduction}</mechanicalReduction>
            <hardwareInterface>VelocityJointInterface</hardwareInterface>
        </actuator>
    </transmission>
    <transmission name="back_right_wheel_axel">
        <type>transmission_interface/SimpleTransmission</type>
        <joint name="back_right_wheel_axel">
            <hardwareInterface>VelocityJointInterface</hardwareInterface>
        </joint>
        <actuator name="back_right_wheel_motor">
        <mechanicalReduction>${gearbox_mechReduction}</mechanicalReduction>
        <hardwareInterface>VelocityJointInterface</hardwareInterface>
        </actuator>
    </transmission>
    <transmission name="laser_tilt_joint">
        <type>transmission_interface/SimpleTransmission</type>
        <joint name="laser_tilt_joint">
            <hardwareInterface>PositionJointInterface</hardwareInterface>
        </joint>
        <actuator name="laser_tilt_motor">
        <mechanicalReduction>${gearbox_mechReduction}</mechanicalReduction>
        <hardwareInterface>PositionJointInterface</hardwareInterface>
        </actuator>
    </transmission>
    
    <!-- hokuyo -->
<!--    <gazebo reference="laser">
        <sensor type="gpu_ray" name="head_hokuyo_sensor">
        <pose>0 0 0 0 0 0</pose>
        <visualize>false</visualize>
        <update_rate>40</update_rate>
        <ray>
            <scan>
            <horizontal>
                <samples>720</samples>
                <resolution>1</resolution>
                <min_angle>-1.570796</min_angle>
                <max_angle>1.570796</max_angle>
            </horizontal>
            </scan>
            <range>
            <min>0.10</min>
            <max>30.0</max>
            <resolution>0.01</resolution>
            </range>
            <noise>
            <type>gaussian</type>-->
            <!-- Noise parameters based on published spec for Hokuyo laser
                achieving "+-30mm" accuracy at range < 10m.  A mean of 0.0m and
                stddev of 0.01m will put 99.7% of samples within 0.03m of the true
                reading. -->
          <!--  <mean>0.0</mean>
            <stddev>0.01</stddev>
            </noise>
        </ray>
        <plugin name="gazebo_ros_head_hokuyo_controller" filename="libgazebo_ros_gpu_laser.so">
            <topicName>/laser/scan</topicName>
            <frameName>laser</frameName>
        </plugin>
        </sensor>
    </gazebo>-->


    <!-- Camera -->
    <joint name="camera0_joint" type="fixed">
        <axis xyz="0 0 0" />
        <origin xyz="1.9 0.1 0.12" rpy="${90 * (PI/180)} ${180 * (PI/180)} 0"/>
        <parent link="robot_base"/>
        <child link="camera0"/>
    </joint>


    <link
        name="camera0">
        <inertial>
        <origin
            xyz="-0.00054683 0.001771 -0.0050465"
            rpy="0 0 0" />
        <mass
            value="0.10277" />
        <inertia
            ixx="6.55247596255939E-05"
            ixy="1.44592890004105E-05"
            ixz="-1.9743090338811E-12"
            iyy="1.49262113028713E-12"
            iyz="-4.87402177304733E-05"
            izz="-1.49262112259026E-12" />
        </inertial>
        <visual>
        <origin
            xyz="1.5707963267949 0 0"
            rpy="0 0 0" />
        <geometry>
            <mesh
            filename="package://owr_bluetounge_tf/meshes/camera.STL" />
        </geometry>
        <material
            name="">
            <color
            rgba="0.79216 0.81961 0.93333 1" />
        </material>
        </visual>
        <collision>
        <origin
            xyz="0 0 0"
            rpy="1.5707963267949 0 0" />
        <geometry>
            <mesh
            filename="package://owr_bluetounge_tf/meshes/camera.STL" />
        </geometry>
        </collision>
    </link>

    <gazebo reference="camera0">
        <sensor type="camera" name="camera0">
            <update_rate>30.0</update_rate>
            <camera name="camera0">
                <!-- source for fov: http://therandomlab.blogspot.com.au/2013/03/logitech-c920-and-c910-fields-of-view.html -->
                <horizontal_fov>1.2290609</horizontal_fov>
                <image>
                <width>1920</width>
                <height>1080</height>
                <format>R8G8B8</format>
                </image>
                <clip>
                <near>0.02</near>
                <far>300</far>
                </clip>
                <noise>
                <type>gaussian</type>
                <!-- Noise is sampled independently per pixel on each frame.
                    That pixel's noise value is added to each of its color
                    channels, which at that point lie in the range [0,1]. -->
                <mean>0.0</mean>
                <stddev>0.007</stddev>
                </noise>
            </camera>
            <plugin name="camera_controller" filename="libgazebo_ros_camera.so">
                <alwaysOn>true</alwaysOn>
                <updateRate>0.0</updateRate>
                <cameraName>camera0</cameraName>
                <imageTopicName>image_raw</imageTopicName>
                <cameraInfoTopicName>camera_info</cameraInfoTopicName>
                <frameName>camera0</frameName>
                <hackBaseline>0.07</hackBaseline>
                <distortionK1>0.0</distortionK1>
                <distortionK2>0.0</distortionK2>
                <distortionK3>0.0</distortionK3>
                <distortionT1>0.0</distortionT1>
                <distortionT2>0.0</distortionT2>
            </plugin>
        </sensor>
</gazebo>


</robot>