<robot
  name="owr_bluetounge_tf">
  <link
    name="base_link">
    <inertial>
      <origin
        xyz="-1.11022302462516E-16 2.40127362438614E-12 -0.0250000000000001"
        rpy="0 0 0" />
      <mass
        value="11.142477796077" />
      <inertia
        ixx="0.0962561371433882"
        ixy="2.27620880556744E-16"
        ixz="1.72396785161265E-17"
        iyy="0.619215971683581"
        iyz="5.65768539139765E-18"
        izz="0.710927584515695" />
    </inertial>
    <visual>
      <origin
        xyz="0 0 0"
        rpy="0 0 0" />
      <geometry>
        <mesh
          filename="package://owr_bluetounge_tf/meshes/base_link.STL" />
      </geometry>
      <material
        name="">
        <color
          rgba="0.792156862745098 0.819607843137255 0.933333333333333 1" />
      </material>
    </visual>
    <collision>
      <origin
        xyz="0 0 0"
        rpy="0 0 0" />
      <geometry>
        <mesh
          filename="package://owr_bluetounge_tf/meshes/base_link.STL" />
      </geometry>
    </collision>
  </link>
  <link
    name="left_linear_base">
    <inertial>
      <origin
        xyz="-1.58206781009085E-15 0.245278144223785 4.1883163603984E-14"
        rpy="0 0 0" />
      <mass
        value="22.0243812744452" />
      <inertia
        ixx="0.675842052997779"
        ixy="-1.42767742072891E-15"
        ixz="-1.74814316481649E-17"
        iyy="0.244857369535637"
        iyz="2.05666850940837E-17"
        izz="0.665911383679203" />
    </inertial>
    <visual>
      <origin
        xyz="0 0 0"
        rpy="0 0 0" />
      <geometry>
        <mesh
          filename="package://owr_bluetounge_tf/meshes/left_linear_base.STL" />
      </geometry>
      <material
        name="">
        <color
          rgba="0.792156862745098 0.819607843137255 0.933333333333333 1" />
      </material>
    </visual>
    <collision>
      <origin
        xyz="0 0 0"
        rpy="0 0 0" />
      <geometry>
        <mesh
          filename="package://owr_bluetounge_tf/meshes/left_linear_base.STL" />
      </geometry>
    </collision>
  </link>
  <joint
    name="left_linear_base_rotate"
    type="continuous">
    <origin
      xyz="-0.400000000000018 0 -0.0249999999999806"
      rpy="-1.5707963267949 0.0556932148995094 -1.49498600701826E-14" />
    <parent
      link="base_link" />
    <child
      link="left_linear_base" />
    <axis
      xyz="0 0 -1" />
  </joint>
  <link
    name="left_linear_shaft">
    <inertial>
      <origin
        xyz="7.36772365339533E-10 0.369536352266734 2.34941321952675E-09"
        rpy="0 0 0" />
      <mass
        value="23.1723954465805" />
      <inertia
        ixx="1.12019270894719"
        ixy="4.9543966350058E-08"
        ixz="2.42000093385165E-08"
        iyy="0.116471092770109"
        iyz="1.96612993948527E-08"
        izz="1.12141055478816" />
    </inertial>
    <visual>
      <origin
        xyz="0 0 0"
        rpy="0 0 0" />
      <geometry>
        <mesh
          filename="package://owr_bluetounge_tf/meshes/left_linear_shaft.STL" />
      </geometry>
      <material
        name="">
        <color
          rgba="0.792156862745098 0.819607843137255 0.933333333333333 1" />
      </material>
    </visual>
    <collision>
      <origin
        xyz="0 0 0"
        rpy="0 0 0" />
      <geometry>
        <mesh
          filename="package://owr_bluetounge_tf/meshes/left_linear_shaft.STL" />
      </geometry>
    </collision>
  </link>
  <joint
    name="left_linear_extension"
    type="prismatic">
    <origin
      xyz="0 0.20488 0"
      rpy="-3.9443E-31 0 1.3184E-16" />
    <parent
      link="left_linear_base" />
    <child
      link="left_linear_shaft" />
    <axis
      xyz="0 1 0" />
    <limit
      lower="0"
      upper="1"
      effort="1000"
      velocity="1000" />
  </joint>
  <link
    name="long_link">
    <inertial>
      <origin
        xyz="0.650000000007444 5.58775248293841E-13 1.44845246907721E-12"
        rpy="0 0 0" />
      <mass
        value="18.642477796077" />
      <inertia
        ixx="0.154068636916015"
        ixy="-3.38271077816095E-17"
        ixz="3.17000657337143E-14"
        iyy="2.7233280057585"
        iyz="2.35207914345893E-15"
        izz="2.57692889315376" />
    </inertial>
    <visual>
      <origin
        xyz="0 0 0"
        rpy="0 0 0" />
      <geometry>
        <mesh
          filename="package://owr_bluetounge_tf/meshes/long_link.STL" />
      </geometry>
      <material
        name="">
        <color
          rgba="0.792156862745098 0.819607843137255 0.933333333333333 1" />
      </material>
    </visual>
    <collision>
      <origin
        xyz="0 0 0"
        rpy="0 0 0" />
      <geometry>
        <mesh
          filename="package://owr_bluetounge_tf/meshes/long_link.STL" />
      </geometry>
    </collision>
  </link>
  <joint
    name="left_linear_shaft_rotate"
    type="continuous">
    <origin
      xyz="0 0.7 0"
      rpy="-1.1427E-16 -1.3215E-16 -0.13669" />
    <parent
      link="left_linear_shaft" />
    <child
      link="long_link" />
    <axis
      xyz="0 0 -1" />
  </joint>
  <link
    name="right_linear_base">
    <inertial>
      <origin
        xyz="-7.99360577730113E-15 0.245278144223794 4.32986979603811E-14"
        rpy="0 0 0" />
      <mass
        value="22.0243812744452" />
      <inertia
        ixx="0.675842052997779"
        ixy="-1.39471767468535E-15"
        ixz="-7.33674970105895E-18"
        iyy="0.244857369535637"
        iyz="-5.89454679574915E-17"
        izz="0.665911383679203" />
    </inertial>
    <visual>
      <origin
        xyz="0 0 0"
        rpy="0 0 0" />
      <geometry>
        <mesh
          filename="package://owr_bluetounge_tf/meshes/right_linear_base.STL" />
      </geometry>
      <material
        name="">
        <color
          rgba="0.792156862745098 0.819607843137255 0.933333333333333 1" />
      </material>
    </visual>
    <collision>
      <origin
        xyz="0 0 0"
        rpy="0 0 0" />
      <geometry>
        <mesh
          filename="package://owr_bluetounge_tf/meshes/right_linear_base.STL" />
      </geometry>
    </collision>
  </link>
  <joint
    name="right_linear_base_rotate"
    type="continuous">
    <origin
      xyz="0.40000000000003 0 -0.0249999999992338"
      rpy="-1.5707963267949 -0.5088897326569 -5.55111512448809E-17" />
    <parent
      link="base_link" />
    <child
      link="right_linear_base" />
    <axis
      xyz="0 0 -1" />
  </joint>
  <link
    name="right_linear_shaft">
    <inertial>
      <origin
        xyz="7.36212424357063E-10 0.369536352267155 2.34942579280251E-09"
        rpy="0 0 0" />
      <mass
        value="23.1723954465805" />
      <inertia
        ixx="1.12019270894719"
        ixy="4.95439664571773E-08"
        ixz="2.42000093384699E-08"
        iyy="0.116471092770109"
        iyz="1.96612922053569E-08"
        izz="1.12141055478816" />
    </inertial>
    <visual>
      <origin
        xyz="0 0 0"
        rpy="0 0 0" />
      <geometry>
        <mesh
          filename="package://owr_bluetounge_tf/meshes/right_linear_shaft.STL" />
      </geometry>
      <material
        name="">
        <color
          rgba="0.792156862745098 0.819607843137255 0.933333333333333 1" />
      </material>
    </visual>
    <collision>
      <origin
        xyz="0 0 0"
        rpy="0 0 0" />
      <geometry>
        <mesh
          filename="package://owr_bluetounge_tf/meshes/right_linear_shaft.STL" />
      </geometry>
    </collision>
  </link>
  <joint
    name="right_linear_extension"
    type="prismatic">
    <origin
      xyz="0 0.21412 0"
      rpy="6.6296E-27 -2.8208E-30 1.6653E-16" />
    <parent
      link="right_linear_base" />
    <child
      link="right_linear_shaft" />
    <axis
      xyz="0 1 0" />
    <limit
      lower="0"
      upper="1"
      effort="1000"
      velocity="1000" />
  </joint>
  <link
    name="long_link2">
    <inertial>
      <origin
        xyz="-0.649999999992625 7.51732009973693E-13 1.38924982628907E-12"
        rpy="0 0 0" />
      <mass
        value="18.642477796077" />
      <inertia
        ixx="0.154068636916015"
        ixy="-5.89805981832732E-17"
        ixz="3.1681337903787E-14"
        iyy="2.7233280057585"
        iyz="2.3524709618966E-15"
        izz="2.57692889315376" />
    </inertial>
    <visual>
      <origin
        xyz="0 0 0"
        rpy="0 0 0" />
      <geometry>
        <mesh
          filename="package://owr_bluetounge_tf/meshes/long_link2.STL" />
      </geometry>
      <material
        name="">
        <color
          rgba="0.792156862745098 0.819607843137255 0.933333333333333 1" />
      </material>
    </visual>
    <collision>
      <origin
        xyz="0 0 0"
        rpy="0 0 0" />
      <geometry>
        <mesh
          filename="package://owr_bluetounge_tf/meshes/long_link2.STL" />
      </geometry>
    </collision>
  </link>
  <joint
    name="right_linear_shaft_rotate"
    type="continuous">
    <origin
      xyz="0 0.699999999996918 0"
      rpy="-1.19874294786595E-15 1.47299632878217E-14 0.427890034635904" />
    <parent
      link="right_linear_shaft" />
    <child
      link="long_link2" />
    <axis
      xyz="0 0 -1" />
  </joint>
</robot>
