<robot
  name="owr_bluetounge_tf">
  <link
    name="base_link">
    <inertial>
      <origin
        xyz="0.0166163751618239 0.0528781229668025 -2.91614648502528E-17"
        rpy="0 0 0" />
      <mass
        value="0.684098692441384" />
      <inertia
        ixx="0.00455045650818714"
        ixy="0.00123222889017576"
        ixz="-2.07082614944731E-17"
        iyy="0.00308597470213886"
        iyz="-9.75781955236954E-19"
        izz="0.00497257421260684" />
    </inertial>
    <visual>
      <origin
        xyz="0 0 0"
        rpy="0 0 0" />
      <geometry>
        <mesh
          filename="package://owr_bluetounge_tf/meshes/base_link.STL" />
      </geometry>
      <material
        name="">
        <color
          rgba="0.866666666666667 0.909803921568627 1 1" />
      </material>
    </visual>
    <collision>
      <origin
        xyz="0 0 0"
        rpy="0 0 0" />
      <geometry>
        <mesh
          filename="package://owr_bluetounge_tf/meshes/base_link.STL" />
      </geometry>
    </collision>
  </link>
  <link
    name="top_actuator_base">
    <inertial>
      <origin
        xyz="3.8386917148159E-07 0.108922375109578 0.0117035699013765"
        rpy="0 0 0" />
      <mass
        value="0.500146440873381" />
      <inertia
        ixx="0.00409615173454252"
        ixy="8.77601716691128E-10"
        ixz="4.68609010140285E-11"
        iyy="0.000312154693900728"
        iyz="-0.000298261699975944"
        izz="0.00390712967398506" />
    </inertial>
    <visual>
      <origin
        xyz="0 0 0"
        rpy="0 0 0" />
      <geometry>
        <mesh
          filename="package://owr_bluetounge_tf/meshes/top_actuator_base.STL" />
      </geometry>
      <material
        name="">
        <color
          rgba="1 1 1 1" />
      </material>
    </visual>
    <collision>
      <origin
        xyz="0 0 0"
        rpy="0 0 0" />
      <geometry>
        <mesh
          filename="package://owr_bluetounge_tf/meshes/top_actuator_base.STL" />
      </geometry>
    </collision>
  </link>
  <joint
    name="top_actuator_base_rotate"
    type="continuous">
    <origin
      xyz="0.0898381894927384 0 0.209155716713238"
      rpy="1.14619501972752 5.59161451734894E-09 1.57079633916291" />
    <parent
      link="base_link" />
    <child
      link="top_actuator_base" />
    <axis
      xyz="1 0 0" />
  </joint>
  <link
    name="top_actuator_shaft">
    <inertial>
      <origin
        xyz="-6.42675071493848E-09 0.141281566918828 -3.89849655723012E-07"
        rpy="0 0 0" />
      <mass
        value="0.707194764725093" />
      <inertia
        ixx="0.00473421933812623"
        ixy="-5.20277564267945E-10"
        ixz="-3.85697240064257E-11"
        iyy="3.53245822418608E-05"
        iyz="7.79526323917001E-10"
        izz="0.00473445875699852" />
    </inertial>
    <visual>
      <origin
        xyz="0 0 0"
        rpy="0 0 0" />
      <geometry>
        <mesh
          filename="package://owr_bluetounge_tf/meshes/top_actuator_shaft.STL" />
      </geometry>
      <material
        name="">
        <color
          rgba="0.647058823529412 0.619607843137255 0.588235294117647 1" />
      </material>
    </visual>
    <collision>
      <origin
        xyz="0 0 0"
        rpy="0 0 0" />
      <geometry>
        <mesh
          filename="package://owr_bluetounge_tf/meshes/top_actuator_shaft.STL" />
      </geometry>
    </collision>
  </link>
  <joint
    name="top_actuator_extension"
    type="prismatic">
    <origin
      xyz="0 0.072106 0"
      rpy="3.1415 -1.5708 -3.1415" />
    <parent
      link="top_actuator_base" />
    <child
      link="top_actuator_shaft" />
    <axis
      xyz="0 1 0" />
    <limit
      lower="-10"
      upper="10"
      effort="1000"
      velocity="1000" />
  </joint>
  <link
    name="sync_main">
    <inertial>
      <origin
        xyz="0.308399703308004 0.06823181965303 -0.042"
        rpy="0 0 0" />
      <mass
        value="0.648821763310334" />
      <inertia
        ixx="0.00312441138952437"
        ixy="0.00210512847022665"
        ixz="7.11476252735312E-16"
        iyy="0.0173867416966378"
        iyz="-2.01258215095913E-15"
        izz="0.0180631349574633" />
    </inertial>
    <visual>
      <origin
        xyz="0 0 0"
        rpy="0 0 0" />
      <geometry>
        <mesh
          filename="package://owr_bluetounge_tf/meshes/sync_main.STL" />
      </geometry>
      <material
        name="">
        <color
          rgba="0.866666666666667 0.909803921568627 1 1" />
      </material>
    </visual>
    <collision>
      <origin
        xyz="0 0 0"
        rpy="0 0 0" />
      <geometry>
        <mesh
          filename="package://owr_bluetounge_tf/meshes/sync_main.STL" />
      </geometry>
    </collision>
  </link>
  <joint
    name="top_actuator_to_sync_main"
    type="continuous">
    <origin
      xyz="-0.115124184387589 -0.175473958284494 -0.0419999999999976"
      rpy="3.14159265358979 0 1.67149338911103" />
    <parent
      link="top_actuator_shaft" />
    <child
      link="sync_main" />
    <axis
      xyz="0 0 -1" />
  </joint>
  <link
    name="structural_main">
    <inertial>
      <origin
        xyz="0.225431734082766 0.0316628590629463 -1.08646810919192E-15"
        rpy="0 0 0" />
      <mass
        value="0.54398717386464" />
      <inertia
        ixx="0.000873596024538067"
        ixy="-0.00164650205345858"
        ixz="5.10170268341929E-18"
        iyy="0.0192872741381462"
        iyz="-1.33169271132364E-19"
        izz="0.0193269664852361" />
    </inertial>
    <visual>
      <origin
        xyz="0 0 0"
        rpy="0 0 0" />
      <geometry>
        <mesh
          filename="package://owr_bluetounge_tf/meshes/structural_main.STL" />
      </geometry>
      <material
        name="">
        <color
          rgba="0.866666666666667 0.909803921568627 1 1" />
      </material>
    </visual>
    <collision>
      <origin
        xyz="0 0 0"
        rpy="0 0 0" />
      <geometry>
        <mesh
          filename="package://owr_bluetounge_tf/meshes/structural_main.STL" />
      </geometry>
    </collision>
  </link>
  <joint
    name="base_to_structural_main"
    type="continuous">
    <origin
      xyz="-0.0275200000000058 0 0.0289999999999882"
      rpy="1.5707963267949 -1.04097774036042 3.14159265358979" />
    <parent
      link="base_link" />
    <child
      link="structural_main" />
    <axis
      xyz="0 0 1" />
  </joint>
  <link
    name="sync_plate">
    <inertial>
      <origin
        xyz="0.0549999999999699 0.0119792194518688 0.0379999999999998"
        rpy="0 0 0" />
      <mass
        value="0.109130569272771" />
      <inertia
        ixx="0.000183895963352781"
        ixy="-9.5231914259801E-18"
        ixz="-1.94322702391329E-16"
        iyy="0.000289451897743207"
        iyz="1.29413170677579E-16"
        izz="0.000190190410689571" />
    </inertial>
    <visual>
      <origin
        xyz="0 0 0"
        rpy="0 0 0" />
      <geometry>
        <mesh
          filename="package://owr_bluetounge_tf/meshes/sync_plate.STL" />
      </geometry>
      <material
        name="">
        <color
          rgba="0.866666666666667 0.909803921568627 1 1" />
      </material>
    </visual>
    <collision>
      <origin
        xyz="0 0 0"
        rpy="0 0 0" />
      <geometry>
        <mesh
          filename="package://owr_bluetounge_tf/meshes/sync_plate.STL" />
      </geometry>
    </collision>
  </link>
  <joint
    name="structural_main_to_sync_plate"
    type="continuous">
    <origin
      xyz="0.600097477062092 -0.0215765064114193 -0.0380000000000022"
      rpy="6.88704600198579E-17 1.01259404278687E-16 2.16806796081584" />
    <parent
      link="structural_main" />
    <child
      link="sync_plate" />
    <axis
      xyz="0 0 -1" />
  </joint>
  <link
    name="sync_minor">
    <inertial>
      <origin
        xyz="0.193924800000125 -9.03721542044877E-14 -0.0380000000000022"
        rpy="0 0 0" />
      <mass
        value="0.246647562813028" />
      <inertia
        ixx="0.000440170999251704"
        ixy="-1.55976035039196E-16"
        ixz="-1.1273572717668E-17"
        iyy="0.00525278378214963"
        iyz="-6.17933126795463E-19"
        izz="0.00485090350786894" />
    </inertial>
    <visual>
      <origin
        xyz="0 0 0"
        rpy="0 0 0" />
      <geometry>
        <mesh
          filename="package://owr_bluetounge_tf/meshes/sync_minor.STL" />
      </geometry>
      <material
        name="">
        <color
          rgba="0.2 0.4 0.698039215686274 1" />
      </material>
    </visual>
    <collision>
      <origin
        xyz="0 0 0"
        rpy="0 0 0" />
      <geometry>
        <mesh
          filename="package://owr_bluetounge_tf/meshes/sync_minor.STL" />
      </geometry>
    </collision>
  </link>
  <joint
    name="sync_plate_to_sync_minor"
    type="continuous">
    <origin
      xyz="0 0 0"
      rpy="3.14159265358979 0 1.88517119022756" />
    <parent
      link="sync_plate" />
    <child
      link="sync_minor" />
    <axis
      xyz="0 0 -1" />
  </joint>
  <link
    name="end_plate">
    <inertial>
      <origin
        xyz="0.0428727282215881 0.0128068845418255 -0.0340000000000013"
        rpy="0 0 0" />
      <mass
        value="0.0752794153885444" />
      <inertia
        ixx="0.000111261417750827"
        ixy="-4.50412524856965E-06"
        ixz="-7.27728317594214E-20"
        iyy="0.000149012718855924"
        iyz="-4.28314796428062E-21"
        izz="6.49491468119236E-05" />
    </inertial>
    <visual>
      <origin
        xyz="0 0 0"
        rpy="0 0 0" />
      <geometry>
        <mesh
          filename="package://owr_bluetounge_tf/meshes/end_plate.STL" />
      </geometry>
      <material
        name="">
        <color
          rgba="0.2 0.4 0.698039215686274 1" />
      </material>
    </visual>
    <collision>
      <origin
        xyz="0 0 0"
        rpy="0 0 0" />
      <geometry>
        <mesh
          filename="package://owr_bluetounge_tf/meshes/end_plate.STL" />
      </geometry>
    </collision>
  </link>
  <joint
    name="sync_minor_to_end_plate"
    type="continuous">
    <origin
      xyz="0.439282685338784 -0.017880203257983 -0.00399999999999935"
      rpy="0 0 1.8863672273632" />
    <parent
      link="sync_minor" />
    <child
      link="end_plate" />
    <axis
      xyz="0 0 -1" />
  </joint>
  <link
    name="rocker">
    <inertial>
      <origin
        xyz="-0.12918041957683 -0.0112469868220725 -0.0179999999999983"
        rpy="0 0 0" />
      <mass
        value="0.441329423356222" />
      <inertia
        ixx="0.000365026101321321"
        ixy="-0.000616265597877472"
        ixz="1.10432801939129E-17"
        iyy="0.0112480592400239"
        iyz="-5.40477408536295E-19"
        izz="0.0112542443528068" />
    </inertial>
    <visual>
      <origin
        xyz="0 0 0"
        rpy="0 0 0" />
      <geometry>
        <mesh
          filename="package://owr_bluetounge_tf/meshes/rocker.STL" />
      </geometry>
      <material
        name="">
        <color
          rgba="0.2 0.4 0.698039215686274 1" />
      </material>
    </visual>
    <collision>
      <origin
        xyz="0 0 0"
        rpy="0 0 0" />
      <geometry>
        <mesh
          filename="package://owr_bluetounge_tf/meshes/rocker.STL" />
      </geometry>
    </collision>
  </link>
  <joint
    name="sync_plate_to_rocker"
    type="continuous">
    <origin
      xyz="0.534024000000006 0 -0.0179999999999996"
      rpy="3.14159265358979 9.70332217454327E-17 0.914672033584322" />
    <parent
      link="structural_main" />
    <child
      link="rocker" />
    <axis
      xyz="0 0 1" />
  </joint>
  <link
    name="bottom_actuator_base">
    <inertial>
      <origin
        xyz="0.0320003878551592 0.107076218808195 -0.0663391676332805"
        rpy="0 0 0" />
      <mass
        value="0.529218600966516" />
      <inertia
        ixx="0.00602555556908908"
        ixy="6.21000936221933E-10"
        ixz="-5.42950147234237E-10"
        iyy="0.00109431938906025"
        iyz="-0.00196006105573982"
        izz="0.00504905973351216" />
    </inertial>
    <visual>
      <origin
        xyz="0 0 0"
        rpy="0 0 0" />
      <geometry>
        <mesh
          filename="package://owr_bluetounge_tf/meshes/bottom_actuator_base.STL" />
      </geometry>
      <material
        name="">
        <color
          rgba="0.647058823529412 0.619607843137255 0.588235294117647 1" />
      </material>
    </visual>
    <collision>
      <origin
        xyz="0 0 0"
        rpy="0 0 0" />
      <geometry>
        <mesh
          filename="package://owr_bluetounge_tf/meshes/bottom_actuator_base.STL" />
      </geometry>
    </collision>
  </link>
  <joint
    name="bottom_actuator_base_rotate"
    type="continuous">
    <origin
      xyz="0 0.0880000000000138 -0.0320000000000025"
      rpy="2.10061491322937 -1.5707963267949 0" />
    <parent
      link="structural_main" />
    <child
      link="bottom_actuator_base" />
    <axis
      xyz="-1 0 0" />
  </joint>
  <link
    name="bottom_actuator_shaft">
    <inertial>
      <origin
        xyz="-6.34969757329351E-09 0.166668233337022 -3.90622096572987E-07"
        rpy="0 0 0" />
      <mass
        value="0.834414950203527" />
      <inertia
        ixx="0.00776037762591338"
        ixy="-7.15075962681318E-10"
        ixz="-4.03514819878724E-11"
        iyy="4.16629664565425E-05"
        iyz="1.00937170105213E-09"
        izz="0.00776061704818279" />
    </inertial>
    <visual>
      <origin
        xyz="0 0 0"
        rpy="0 0 0" />
      <geometry>
        <mesh
          filename="package://owr_bluetounge_tf/meshes/bottom_actuator_shaft.STL" />
      </geometry>
      <material
        name="">
        <color
          rgba="0.647058823529412 0.619607843137255 0.588235294117647 1" />
      </material>
    </visual>
    <collision>
      <origin
        xyz="0 0 0"
        rpy="0 0 0" />
      <geometry>
        <mesh
          filename="package://owr_bluetounge_tf/meshes/bottom_actuator_shaft.STL" />
      </geometry>
    </collision>
  </link>
  <joint
    name="bottom_actuator_extension"
    type="prismatic">
    <origin
      xyz="0.032 0.21857 -0.11088"
      rpy="-1.5708 -1.1013 1.5708" />
    <parent
      link="bottom_actuator_base" />
    <child
      link="bottom_actuator_shaft" />
    <axis
      xyz="0 1 0" />
    <limit
      lower="-10"
      upper="10"
      effort="1000"
      velocity="1000" />
  </joint>
</robot>